Workbook

Sheet PEDIDO
I2: NUMERO DO PEDIDO | N2: 500 | W2: COMPRADOR | AK2: DATA | AN2: =TODAY() -> 46057
I3: MARCA | W3: REPRESENTANTE | AK3: TEL.
I4: FORNECEDOR | W4: EMAIL | AK4: FRETE | AN4: CIF
I5: PRAZO DE PAG. | N5: 90 | Q5: 120 | T5: 150 | W5: FATURAMENTO | AF5: LIMITE | AK5: CREDITO | AN5: SIM
I6: VENC. DUPLICATAS | N6: =N5+AA5 -> 90 | Q6: =Q5+AA5 -> 120 | T6: =T5+AA5 -> 150 | W6: DESCONTO: | AD6: MARKUP:
I8: OBSERVAÇÕES: | M8: CASO HAJA DIVERGÊNCIAS, ERROS OU ALTERAÇÕES , DEVEM SER APRESENTADOS EM ATÉ 7 DIAS APÓS A DATA DE ENVIO DO PEDIDO *
I9: TODAS AS REFERENCIAS DEVEM CONSTAR NA NOTA FISCAL DA MESMA FORMA QUE CONSTA NO PEDIDO * SUJEITO A DEVOLUÇÃO NO ATO DA
I10: ENTREGA EM CASO DE DIVERGÊNCIA
B13: GRADE | D13: UN | E13: P | F13: M | G13: G | H13: GG | I13: 16 | J13: 17 | K13: 18 | L13: 19 | M13: 20 | N13: 21 | O13: 22 | P13: 23 | Q13: 24 | R13: 25 | S13: 26 | T13: 27 | U13: 28 | V13: 29 | W13: 30 | X13: 31 | Y13: 32 | Z13: 33 | AA13: 34 | AB13: 35 | AC13: 36 | AD13: 37 | AE13: 38 | AF13: 39 | AG13: 40 | AH13: 41 | AI13: 42 | AJ13: 43 | AK13: 44 | AL13: 45 | AM13: 46 | AN13: 47 | AO13: 48 | AP13: TOTAL
B14: A | AP14: =SUM(D14:AO14) -> 0 | AY14: =IF(COUNTA(PEDIDO!$I$14:$AO$21)>0,"NUMERICO","")
B15: B | AP15: =SUM(D15:AO15) -> 0 | AY15: =IF(COUNTA(PEDIDO!$D$14:$H$21)>0,"ALFANUMERICO","")
B16: C | AP16: =SUM(D16:AO16) -> 0
B17: D | AP17: =SUM(D17:AO17) -> 0
B18: E | AP18: =SUM(D18:AO18) -> 0
B19: F | AP19: =SUM(D19:AO19) -> 0
B20: G | AP20: =SUM(D20:AO20) -> 0
B21: H | AP21: =SUM(D21:AO21) -> 0 | BF21: 49
BF22: 70
B23: =W29 -> PEDIDO 1 | AP23: =COUNT(D23:AO23) -> 0 | BF23: 70
B24: =Z29 -> PEDIDO 2 | AP24: =COUNT(D24:AO24) -> 0 | BF24: 000
B25: =AC29 -> PEDIDO 3 | AP25: =COUNT(D25:AO25) -> 0
B26: =AF29 -> PEDIDO 4 | AP26: =COUNT(D26:AO26) -> 0 | BF26: UN
B27: =AI29 -> PEDIDO 5 | AP27: =COUNT(D27:AO27) -> 0 | BF27: 64042000
B28: N/C | D28: 2 | F28: 4 | G28: 5 | H28: 12 | I28: 13 | J28: 14 | K28: 19 | L28: 32 | M28: 33 | N28: 35 | O28: 37 | P28: 38 | Q28: 46 | R28: 47 | S28: 49 | T28: 51 | U28: 57 | V28: 74 | W28: 77 | X28: 79 | Y28: 81 | Z28: 83 | AA28: 84 | AB28: 85 | AC28: 87 | AD28: 90 | AE28: 91 | AF28: 92 | AG28: 93 | AH28: 94 | AI28: 97 | AJ28: 98 | AP28: =COUNT(D28:AO28) -> 32
B29: PEDIDOS | W29: PEDIDO 1 | Z29: PEDIDO 2 | AC29: PEDIDO 3 | AF29: PEDIDO 4 | AI29: PEDIDO 5 | AL29: TOTAL DE LOJAS | AP29: =SUM(AP23:AQ27) -> 0 | BF29: 2805900
B30: QUANTIDADES DE PARES / CAIXAS | W30: =SUM(W36:W164) -> 0 | Y30: =W30/12 -> 0 | Z30: =SUM(Z36:Z164) -> 0 | AB30: =Z30/12 -> 0 | AC30: =SUM(AC36:AC164) -> 0 | AE30: =AC30/12 -> 0 | AF30: =SUM(AF36:AF164) -> 0 | AH30: =AF30/12 -> 0 | AI30: =SUM(AI36:AI164) -> 0 | AK30: =AI30/12 -> 0 | AL30: TOTAL DE ÍTENS
B31: VALOR BRUTO | W31: =SUM(AS166) -> 0 | Z31: =SUM(AT166) -> 0 | AC31: =SUM(AU166) -> 0 | AF31: =SUM(AV166) -> 0 | AI31: =SUM(AW166) -> 0 | AL31: =(W30*AP23)+(Z30*AP24)+(AC30*AP25)+(AF30*AP27) -> 0
B32: VALOR LIQUIDO | W32: =W31-(W31*Z6) -> 0 | Z32: =Z31-(Z31*Z6) -> 0 | AC32: =AC31-(AC31*Z6) -> 0 | AF32: =AF31-(AF31*Z6) -> 0 | AI32: =AI31-(AI31*Z6) -> 0 | AY32: SUGESTÃO DE PREÇO (CUSTO - DESC * MKP)
B34: REFERÊNCIA | H34: TIPO | R34: COR 1 | S34: COR 2 | T34: COR 3 | U34: MODELO | W34: 1 | X34: GRADE | Z34: 2 | AA34: GRADE | AC34: 3 | AD34: GRADE | AF34: 4 | AG34: GRADE | AI34: 5 | AJ34: GRADE | AL34: CUSTO | AO34: VENDA | AS34: PEDIDO 1 | AT34: PEDIDO 2 | AU34: PEDIDO 3 | AV34: PEDIDO 4 | AW34: PEDIDO 5
B36: 1 | S36: =IF(R36<>"",R36,"") | T36: =IF(R36<>"",R36,"") | W36: =IFERROR(INDEX($AP$14:$AP$21,MATCH(X36,$B$14:$B$21,0)),"") | Z36: =IFERROR(INDEX($AP$14:$AP$21,MATCH(AA36,$B$14:$B$21,0)),"") | AC36: =IFERROR(INDEX($AP$14:$AP$21,MATCH(AD36,$B$14:$B$21,0)),"") | AF36: =IFERROR(INDEX($AP$14:$AP$21,MATCH(AG36,$B$14:$B$21,0)),"") | AI36: =IFERROR(INDEX($AP$14:$AP$21,MATCH(AJ36,$B$14:$B$21,0)),"") | AS36: =IF(OR(AL36="",W36=""),"",AL36*W36) | AT36: =IF(OR(AL36="",Z36=""),"",AL36*Z36) | AU36: =IF(OR(AL36="",AC36=""),"",AL36*AC36) | AV36: =IF(OR(AL36="",AF36=""),"",AL36*AF36) | AW36: =IF(OR(AL36="",AI36=""),"",AL36*AI36) | AX36: =IF(OR(AL36="",AI36=""),"",AL36*W36) | AY36: =(AL36-(AL36*$Z$6))*$AF$6 -> 0 | BC36: =(AL36-(AL36*$Z$6)) -> 0 | BE36: P
B37: 2 | S37: =IF(R37<>"",R37,"") | T37: =IF(R37<>"",R37,"") | W37: =IFERROR(INDEX($AP$14:$AP$21,MATCH(X37,$B$14:$B$21,0)),"") | Z37: =IFERROR(INDEX($AP$14:$AP$21,MATCH(AA37,$B$14:$B$21,0)),"") | AC37: =IFERROR(INDEX($AP$14:$AP$21,MATCH(AD37,$B$14:$B$21,0)),"") | AF37: =IFERROR(INDEX($AP$14:$AP$21,MATCH(AG37,$B$14:$B$21,0)),"") | AI37: =IFERROR(INDEX($AP$14:$AP$21,MATCH(AJ37,$B$14:$B$21,0)),"") | AR37: =AO37*AI6 -> 0 | AS37: =IF(OR(AL37="",W37=""),"",AL37*W37) | AT37: =IF(OR(AL37="",Z37=""),"",AL37*Z37) | AU37: =IF(OR(AL37="",AC37=""),"",AL37*AC37) | AV37: =IF(OR(AL37="",AF37=""),"",AL37*AF37) | AW37: =IF(OR(AL37="",AI37=""),"",AL37*AI37) | AX37: =IF(OR(AL37="",AI37=""),"",AL37*W37) | AY37: =(AL37-(AL37*$Z$6))*$AF$6 -> 0 | BC37: =(AL37-(AL37*$Z$6)) -> 0 | BE37: T
B38: 3 | S38: =IF(R38<>"",R38,"") | T38: =IF(R38<>"",R38,"") | W38: =IFERROR(INDEX($AP$14:$AP$21,MATCH(X38,$B$14:$B$21,0)),"") | Z38: =IFERROR(INDEX($AP$14:$AP$21,MATCH(AA38,$B$14:$B$21,0)),"") | AC38: =IFERROR(INDEX($AP$14:$AP$21,MATCH(AD38,$B$14:$B$21,0)),"") | AF38: =IFERROR(INDEX($AP$14:$AP$21,MATCH(AG38,$B$14:$B$21,0)),"") | AI38: =IFERROR(INDEX($AP$14:$AP$21,MATCH(AJ38,$B$14:$B$21,0)),"") | AS38: =IF(OR(AL38="",W38=""),"",AL38*W38) | AT38: =IF(OR(AL38="",Z38=""),"",AL38*Z38) | AU38: =IF(OR(AL38="",AC38=""),"",AL38*AC38) | AV38: =IF(OR(AL38="",AF38=""),"",AL38*AF38) | AW38: =IF(OR(AL38="",AI38=""),"",AL38*AI38) | AX38: =IF(OR(AL38="",AI38=""),"",AL38*W38) | AY38: =(AL38-(AL38*$Z$6))*$AF$6 -> 0 | BC38: =(AL38-(AL38*$Z$6)) -> 0 | CD38: ANABELA;
B39: 4 | S39: =IF(R39<>"",R39,"") | T39: =IF(R39<>"",R39,"") | W39: =IFERROR(INDEX($AP$14:$AP$21,MATCH(X39,$B$14:$B$21,0)),"") | Z39: =IFERROR(INDEX($AP$14:$AP$21,MATCH(AA39,$B$14:$B$21,0)),"") | AC39: =IFERROR(INDEX($AP$14:$AP$21,MATCH(AD39,$B$14:$B$21,0)),"") | AF39: =IFERROR(INDEX($AP$14:$AP$21,MATCH(AG39,$B$14:$B$21,0)),"") | AI39: =IFERROR(INDEX($AP$14:$AP$21,MATCH(AJ39,$B$14:$B$21,0)),"") | AS39: =IF(OR(AL39="",W39=""),"",AL39*W39) | AT39: =IF(OR(AL39="",Z39=""),"",AL39*Z39) | AU39: =IF(OR(AL39="",AC39=""),"",AL39*AC39) | AV39: =IF(OR(AL39="",AF39=""),"",AL39*AF39) | AW39: =IF(OR(AL39="",AI39=""),"",AL39*AI39) | AX39: =IF(OR(AL39="",AI39=""),"",AL39*W39) | AY39: =(AL39-(AL39*$Z$6))*$AF$6 -> 0 | BC39: =(AL39-(AL39*$Z$6)) -> 0 | CD39: ANABELA INFANTIL;
B40: 5 | S40: =IF(R40<>"",R40,"") | T40: =IF(R40<>"",R40,"") | W40: =IFERROR(INDEX($AP$14:$AP$21,MATCH(X40,$B$14:$B$21,0)),"") | Z40: =IFERROR(INDEX($AP$14:$AP$21,MATCH(AA40,$B$14:$B$21,0)),"") | AC40: =IFERROR(INDEX($AP$14:$AP$21,MATCH(AD40,$B$14:$B$21,0)),"") | AF40: =IFERROR(INDEX($AP$14:$AP$21,MATCH(AG40,$B$14:$B$21,0)),"") | AI40: =IFERROR(INDEX($AP$14:$AP$21,MATCH(AJ40,$B$14:$B$21,0)),"") | AS40: =IF(OR(AL40="",W40=""),"",AL40*W40) | AT40: =IF(OR(AL40="",Z40=""),"",AL40*Z40) | AU40: =IF(OR(AL40="",AC40=""),"",AL40*AC40) | AV40: =IF(OR(AL40="",AF40=""),"",AL40*AF40) | AW40: =IF(OR(AL40="",AI40=""),"",AL40*AI40) | AX40: =IF(OR(AL40="",AI40=""),"",AL40*W40) | AY40: =(AL40-(AL40*$Z$6))*$AF$6 -> 0 | BC40: =(AL40-(AL40*$Z$6)) -> 0 | CD40: ANEL;
B41: 6 | S41: =IF(R41<>"",R41,"") | T41: =IF(R41<>"",R41,"") | W41: =IFERROR(INDEX($AP$14:$AP$21,MATCH(X41,$B$14:$B$21,0)),"") | Z41: =IFERROR(INDEX($AP$14:$AP$21,MATCH(AA41,$B$14:$B$21,0)),"") | AC41: =IFERROR(INDEX($AP$14:$AP$21,MATCH(AD41,$B$14:$B$21,0)),"") | AF41: =IFERROR(INDEX($AP$14:$AP$21,MATCH(AG41,$B$14:$B$21,0)),"") | AI41: =IFERROR(INDEX($AP$14:$AP$21,MATCH(AJ41,$B$14:$B$21,0)),"") | AS41: =IF(OR(AL41="",W41=""),"",AL41*W41) | AT41: =IF(OR(AL41="",Z41=""),"",AL41*Z41) | AU41: =IF(OR(AL41="",AC41=""),"",AL41*AC41) | AV41: =IF(OR(AL41="",AF41=""),"",AL41*AF41) | AW41: =IF(OR(AL41="",AI41=""),"",AL41*AI41) | AX41: =IF(OR(AL41="",AI41=""),"",AL41*W41) | AY41: =(AL41-(AL41*$Z$6))*$AF$6 -> 0 | BC41: =(AL41-(AL41*$Z$6)) -> 0 | CD41: AROMATIZANTE;
B42: 7 | S42: =IF(R42<>"",R42,"") | T42: =IF(R42<>"",R42,"") | W42: =IFERROR(INDEX($AP$14:$AP$21,MATCH(X42,$B$14:$B$21,0)),"") | Z42: =IFERROR(INDEX($AP$14:$AP$21,MATCH(AA42,$B$14:$B$21,0)),"") | AC42: =IFERROR(INDEX($AP$14:$AP$21,MATCH(AD42,$B$14:$B$21,0)),"") | AF42: =IFERROR(INDEX($AP$14:$AP$21,MATCH(AG42,$B$14:$B$21,0)),"") | AI42: =IFERROR(INDEX($AP$14:$AP$21,MATCH(AJ42,$B$14:$B$21,0)),"") | AS42: =IF(OR(AL42="",W42=""),"",AL42*W42) | AT42: =IF(OR(AL42="",Z42=""),"",AL42*Z42) | AU42: =IF(OR(AL42="",AC42=""),"",AL42*AC42) | AV42: =IF(OR(AL42="",AF42=""),"",AL42*AF42) | AW42: =IF(OR(AL42="",AI42=""),"",AL42*AI42) | AX42: =IF(OR(AL42="",AI42=""),"",AL42*W42) | AY42: =(AL42-(AL42*$Z$6))*$AF$6 -> 0 | BC42: =(AL42-(AL42*$Z$6)) -> 0 | CD42: BABUCHE;
B43: 8 | S43: =IF(R43<>"",R43,"") | T43: =IF(R43<>"",R43,"") | W43: =IFERROR(INDEX($AP$14:$AP$21,MATCH(X43,$B$14:$B$21,0)),"") | Z43: =IFERROR(INDEX($AP$14:$AP$21,MATCH(AA43,$B$14:$B$21,0)),"") | AC43: =IFERROR(INDEX($AP$14:$AP$21,MATCH(AD43,$B$14:$B$21,0)),"") | AF43: =IFERROR(INDEX($AP$14:$AP$21,MATCH(AG43,$B$14:$B$21,0)),"") | AI43: =IFERROR(INDEX($AP$14:$AP$21,MATCH(AJ43,$B$14:$B$21,0)),"") | AS43: =IF(OR(AL43="",W43=""),"",AL43*W43) | AT43: =IF(OR(AL43="",Z43=""),"",AL43*Z43) | AU43: =IF(OR(AL43="",AC43=""),"",AL43*AC43) | AV43: =IF(OR(AL43="",AF43=""),"",AL43*AF43) | AW43: =IF(OR(AL43="",AI43=""),"",AL43*AI43) | AX43: =IF(OR(AL43="",AI43=""),"",AL43*W43) | AY43: =(AL43-(AL43*$Z$6))*$AF$6 -> 0 | BC43: =(AL43-(AL43*$Z$6)) -> 0 | CD43: BABUCHE FEMININO;
B44: 9 | S44: =IF(R44<>"",R44,"") | T44: =IF(R44<>"",R44,"") | W44: =IFERROR(INDEX($AP$14:$AP$21,MATCH(X44,$B$14:$B$21,0)),"") | Z44: =IFERROR(INDEX($AP$14:$AP$21,MATCH(AA44,$B$14:$B$21,0)),"") | AC44: =IFERROR(INDEX($AP$14:$AP$21,MATCH(AD44,$B$14:$B$21,0)),"") | AF44: =IFERROR(INDEX($AP$14:$AP$21,MATCH(AG44,$B$14:$B$21,0)),"") | AI44: =IFERROR(INDEX($AP$14:$AP$21,MATCH(AJ44,$B$14:$B$21,0)),"") | AS44: =IF(OR(AL44="",W44=""),"",AL44*W44) | AT44: =IF(OR(AL44="",Z44=""),"",AL44*Z44) | AU44: =IF(OR(AL44="",AC44=""),"",AL44*AC44) | AV44: =IF(OR(AL44="",AF44=""),"",AL44*AF44) | AW44: =IF(OR(AL44="",AI44=""),"",AL44*AI44) | AX44: =IF(OR(AL44="",AI44=""),"",AL44*W44) | AY44: =(AL44-(AL44*$Z$6))*$AF$6 -> 0 | BC44: =(AL44-(AL44*$Z$6)) -> 0 | CD44: BABUCHE INFANTIL;
B45: 10 | S45: =IF(R45<>"",R45,"") | T45: =IF(R45<>"",R45,"") | W45: =IFERROR(INDEX($AP$14:$AP$21,MATCH(X45,$B$14:$B$21,0)),"") | Z45: =IFERROR(INDEX($AP$14:$AP$21,MATCH(AA45,$B$14:$B$21,0)),"") | AC45: =IFERROR(INDEX($AP$14:$AP$21,MATCH(AD45,$B$14:$B$21,0)),"") | AF45: =IFERROR(INDEX($AP$14:$AP$21,MATCH(AG45,$B$14:$B$21,0)),"") | AI45: =IFERROR(INDEX($AP$14:$AP$21,MATCH(AJ45,$B$14:$B$21,0)),"") | AS45: =IF(OR(AL45="",W45=""),"",AL45*W45) | AT45: =IF(OR(AL45="",Z45=""),"",AL45*Z45) | AU45: =IF(OR(AL45="",AC45=""),"",AL45*AC45) | AV45: =IF(OR(AL45="",AF45=""),"",AL45*AF45) | AW45: =IF(OR(AL45="",AI45=""),"",AL45*AI45) | AX45: =IF(OR(AL45="",AI45=""),"",AL45*W45) | AY45: =(AL45-(AL45*$Z$6))*$AF$6 -> 0 | BC45: =(AL45-(AL45*$Z$6)) -> 0 | CD45: BABUCHE INFANTIL FEMININA;
B46: 11 | S46: =IF(R46<>"",R46,"") | T46: =IF(R46<>"",R46,"") | W46: =IFERROR(INDEX($AP$14:$AP$21,MATCH(X46,$B$14:$B$21,0)),"") | Z46: =IFERROR(INDEX($AP$14:$AP$21,MATCH(AA46,$B$14:$B$21,0)),"") | AC46: =IFERROR(INDEX($AP$14:$AP$21,MATCH(AD46,$B$14:$B$21,0)),"") | AF46: =IFERROR(INDEX($AP$14:$AP$21,MATCH(AG46,$B$14:$B$21,0)),"") | AI46: =IFERROR(INDEX($AP$14:$AP$21,MATCH(AJ46,$B$14:$B$21,0)),"") | AS46: =IF(OR(AL46="",W46=""),"",AL46*W46) | AT46: =IF(OR(AL46="",Z46=""),"",AL46*Z46) | AU46: =IF(OR(AL46="",AC46=""),"",AL46*AC46) | AV46: =IF(OR(AL46="",AF46=""),"",AL46*AF46) | AW46: =IF(OR(AL46="",AI46=""),"",AL46*AI46) | AX46: =IF(OR(AL46="",AI46=""),"",AL46*W46) | AY46: =(AL46-(AL46*$Z$6))*$AF$6 -> 0 | BC46: =(AL46-(AL46*$Z$6)) -> 0 | CD46: BABUCHE INFANTIL MASCULINO;
...

Sheet TABELA
A1: Lojas | B1: 1 | C1: 2 | D1: 3 | E1: 4 | F1: 5 | G1: 6 | H1: 7 | I1: 8 | J1: 9 | K1: 10 | L1: 11 | M1: 12 | N1: 13 | O1: 14 | P1: 15 | Q1: 19 | R1: 20 | S1: 21 | T1: 22 | U1: 23 | V1: 24 | W1: 25 | X1: 26 | Y1: 27 | Z1: 28 | AA1: 29 | AB1: 30 | AC1: 31 | AD1: 32 | AE1: 33 | AF1: 34 | AG1: 35 | AH1: 36 | AI1: 37 | AJ1: 38 | AK1: 39 | AL1: 40 | AM1: 41 | AN1: 42 | AO1: 43 | AP1: 44 | AQ1: 45 | AR1: 46 | AS1: 47 | AT1: 48 | AU1: 49 | AV1: 50 | AW1: 51 | AX1: 52 | AY1: 53 | AZ1: 54 | BA1: 56 | BB1: 57 | BC1: 58 | BD1: 59 | BE1: 60 | BF1: 61 | BG1: 62 | BH1: 63 | BI1: 64 | BJ1: 65 | BK1: 66 | BL1: 67 | BM1: 68 | BN1: 69 | BO1: 70 | BP1: 72 | BQ1: 73 | BR1: 74 | BS1: 75 | BT1: 76 | BU1: 77 | BV1: 78 | BW1: 79 | BX1: 80 | BY1: 81 | BZ1: 82 | CA1: 83 | CB1: 84 | CC1: 85 | CD1: 86 | CE1: 87 | CF1: 88 | CG1: 89 | CH1: 90 | CI1: 91 | CJ1: 92 | CK1: 93 | CL1: 94 | CM1: 95 | CN1: 96 | CO1: 97 | CP1: 98 | CQ1: 99 | CR1: 100 | CS1: 101 | CT1: 102 | CU1: 103 | CV1: 104 | CW1: 105 | CX1: 106 | CY1: 107 | CZ1: 108 | DA1: 999 | DB1: 109 | DC1: 110 | DD1: 111 | DE1: 112 | DF1: 113 | DG1: 114 | DH1: 115 | DI1: 116 | DJ1: 117 | DK1: 118 | DL1: 119 | DM1: 120 | DY1: tipo | DZ1: forncedor | EA1: KAMYSTORE | EB1: PINOLI | EC1: MATIS X
CW2: =IF(COUNTIF(PEDIDO!$D$23:$AO$23, CW$1)>0, CW$1, "") | CX2: =IF(COUNTIF(PEDIDO!$D$23:$AO$23, CX$1)>0, CX$1, "") | CY2: =IF(COUNTIF(PEDIDO!$D$23:$AO$23, CY$1)>0, CY$1, "") | CZ2: =IF(COUNTIF(PEDIDO!$D$23:$AO$23, CZ$1)>0, CZ$1, "") | DA2: =IF(COUNTIF(PEDIDO!$D$23:$AO$23, DA$1)>0, DA$1, "") | DY2: ANABELA | DZ2: POWER GLASSES | EA2: 100 MORENA | EB2: ACADEMY | EC2: NK6 PRO TREKKING
DY3: ANABELA INFANTIL | DZ3: CASA DO FILTRO | EA3: 100 PLUS | EB3: ACAI | EC3: 20L
A4: =PEDIDO!B23 -> PEDIDO 1 | B4: =IF(PEDIDO!D23<>"",PEDIDO!D23,"") | C4: =IF(PEDIDO!E23<>"",PEDIDO!E23,"") | D4: =IF(PEDIDO!F23<>"",PEDIDO!F23,"") | E4: =IF(PEDIDO!G23<>"",PEDIDO!G23,"") | F4: =IF(PEDIDO!H23<>"",PEDIDO!H23,"") | G4: =IF(PEDIDO!I23<>"",PEDIDO!I23,"") | H4: =IF(PEDIDO!J23<>"",PEDIDO!J23,"") | I4: =IF(PEDIDO!K23<>"",PEDIDO!K23,"") | ... AM4: =IF(PEDIDO!AO23<>"",PEDIDO!AO23,"") | AO4: =IF(PEDIDO!AQ23<>"",PEDIDO!AQ23,"") | AP4: =IF(PEDIDO!AR23<>"",PEDIDO!AR23,"") | AQ4: =IF(PEDIDO!AS23<>"",PEDIDO!AS23,"") | AR4: =IF(PEDIDO!AT23<>"",PEDIDO!AT23,"") | AS4: =IF(PEDIDO!AU23<>"",PEDIDO!AU23,"") | AT4: =IF(PEDIDO!AV23<>"",PEDIDO!AV23,"") | AU4: =IF(PEDIDO!AW23<>"",PEDIDO!AW23,"") | AV4: =IF(PEDIDO!AX23<>"",PEDIDO!AX23,"") | ... BC4: =IF(PEDIDO!BE23<>"",PEDIDO!BE23,"") | DY4: ANEL | DZ4: MUSA FASHION | EA4: 2 RIOS | EB4: ACEROLA | EC4: 3 PECA
A5: =PEDIDO!B24 -> PEDIDO 2 | B5: =IF(PEDIDO!D24<>"",PEDIDO!D24,"") | C5: =IF(PEDIDO!E24<>"",PEDIDO!E24,"") | D5: =IF(PEDIDO!F24<>"",PEDIDO!F24,"") | E5: =IF(PEDIDO!G24<>"",PEDIDO!G24,"") | F5: =IF(PEDIDO!H24<>"",PEDIDO!H24,"") | G5: =IF(PEDIDO!I24<>"",PEDIDO!I24,"") | H5: =IF(PEDIDO!J24<>"",PEDIDO!J24,"") | I5: =IF(PEDIDO!K24<>"",PEDIDO!K24,"") | ... AM5: =IF(PEDIDO!AO24<>"",PEDIDO!AO24,"") | DY5: AROMATIZANTE | DZ5: NC | EA5: 206OZ | EB5: ACID LIME | EC5: 360 4 LIFE
A6: =PEDIDO!B25 -> PEDIDO 3 | B6: =IF(PEDIDO!D25<>"",PEDIDO!D25,"") | C6: =IF(PEDIDO!E25<>"",PEDIDO!E25,"") | D6: =IF(PEDIDO!F25<>"",PEDIDO!F25,"") | E6: =IF(PEDIDO!G25<>"",PEDIDO!G25,"") | F6: =IF(PEDIDO!H25<>"",PEDIDO!H25,"") | G6: =IF(PEDIDO!I25<>"",PEDIDO!I25,"") | H6: =IF(PEDIDO!J25<>"",PEDIDO!J25,"") | I6: =IF(PEDIDO!K25<>"",PEDIDO!K25,"") | ... AM6: =IF(PEDIDO!AO25<>"",PEDIDO!AO25,"") | DY6: BABUCHE | DZ6: ISABEL KARINE SANTANA SILVA ALVES | EA6: 23 GRAUS | EB6: ACO | EC6: 360 ATLANTA
A7: =PEDIDO!B26 -> PEDIDO 4 | B7: =IF(PEDIDO!D26<>"",PEDIDO!D26,"") | C7: =IF(PEDIDO!E26<>"",PEDIDO!E26,"") | D7: =IF(PEDIDO!F26<>"",PEDIDO!F26,"") | E7: =IF(PEDIDO!G26<>"",PEDIDO!G26,"") | F7: =IF(PEDIDO!H26<>"",PEDIDO!H26,"") | G7: =IF(PEDIDO!I26<>"",PEDIDO!I26,"") | H7: =IF(PEDIDO!J26<>"",PEDIDO!J26,"") | I7: =IF(PEDIDO!K26<>"",PEDIDO!K26,"") | ... AM7: =IF(PEDIDO!AO26<>"",PEDIDO!AO26,"") | DY7: BABUCHE FEMININO | DZ7: GMAD | EA7: 2K | EB7: ACO INOX | EC7: 360 GAMA
A8: =PEDIDO!B27 -> PEDIDO 5 | B8: =IF(PEDIDO!D27<>"",PEDIDO!D27,"") | C8: =IF(PEDIDO!E27<>"",PEDIDO!E27,"") | D8: =IF(PEDIDO!F27<>"",PEDIDO!F27,"") | E8: =IF(PEDIDO!G27<>"",PEDIDO!G27,"") | F8: =IF(PEDIDO!H27<>"",PEDIDO!H27,"") | G8: =IF(PEDIDO!I27<>"",PEDIDO!I27,"") | H8: =IF(PEDIDO!J27<>"",PEDIDO!J27,"") | I8: =IF(PEDIDO!K27<>"",PEDIDO!K27,"") | ... AM8: =IF(PEDIDO!AO27<>"",PEDIDO!AO27,"") | DY8: BABUCHE INFANTIL | DZ8: GIBIZINHO | EA8: 4R BABY | EB8: ACQUA | EC8: 360 GAMA 3
DY9: BABUCHE INFANTIL FEMININA | DZ9: LIFE GYM | EA9: 4S | EB9: ACQUA WHITE | EC9: 360 GENEBRA
A10: Itens | B10: PEDIDO 1 | C10: PEDIDO 2 | D10: PEDIDO 3 | E10: PEDIDO 4 | F10: PEDIDO 5 | J10: Lojas | K10: 1 | L10: 2 | M10: 3 | N10: 4 | O10: 5 | P10: 6 | Q10: 7 | R10: 8 | S10: 9 | T10: 10 | U10: 11 | V10: 12 | W10: 13 | X10: 14 | Y10: 15 | Z10: 19 | AA10: 20 | AB10: 21 | AC10: 22 | AD10: 23 | AE10: 24 | AF10: 25 | AG10: 26 | AH10: 27 | AI10: 28 | AJ10: 29 | AK10: 30 | AL10: 31 | AM10: 32 | AN10: 33 | AO10: 34 | AP10: 35 | AQ10: 36 | AR10: 37 | AS10: 38 | AT10: 39 | AU10: 40 | AV10: 41 | AW10: 42 | AX10: 43 | AY10: 44 | AZ10: 45 | BA10: 46 | BB10: 47 | BC10: 48 | BD10: 49 | BE10: 50 | BF10: 51 | BG10: 52 | BH10: 53 | BI10: 54 | BJ10: 56 | BK10: 57 | BL10: 58 | BM10: 59 | BN10: 60 | BO10: 61 | BP10: 62 | BQ10: 63 | BR10: 64 | BS10: 65 | BT10: 66 | BU10: 67 | BV10: 68 | BW10: 69 | BX10: 70 | BY10: 72 | BZ10: 73 | CA10: 74 | CB10: 75 | CC10: 76 | CD10: 77 | CE10: 78 | CF10: 79 | CG10: 80 | CH10: 81 | CI10: 82 | CJ10: 83 | CK10: 84 | CL10: 85 | CM10: 86 | CN10: 87 | CO10: 88 | CP10: 89 | CQ10: 90 | CR10: 91 | CS10: 92 | CT10: 93 | CU10: 94 | CV10: 95 | CW10: 96 | CX10: 97 | CY10: 98 | CZ10: 99 | DA10: 100 | DB10: 101 | DC10: 102 | DD10: 103 | DE10: 104 | DF10: 105 | DG10: 106 | DH10: 107 | DI10: 108 | DJ10: 999 | DK10: 109 | DL10: 110 | DM10: 111 | DN10: 112 | DO10: 113 | DP10: 114 | DQ10: 115 | DR10: 116 | DS10: 117 | DT10: 118 | DU10: 119 | DV10: 120 | DY10: BABUCHE INFANTIL MASCULINO | DZ10: IMPERIO MOVEIS E ELETRO | EA10: 5 GERAÇÃO | EB10: ADAMES COLORS | EC10: 360 RACER
A11: =IF(PEDIDO!C36<>"",PEDIDO!B36,"") | B11: =IF(PEDIDO!X36<>"",PEDIDO!X36,"") | C11: =IF(PEDIDO!AA36<>"",PEDIDO!AA36,"") | D11: =IF(PEDIDO!AD36<>"",PEDIDO!AD36,"") | E11: =IF(PEDIDO!AG36<>"",PEDIDO!AG36,"") | F11: =IF(PEDIDO!AJ36<>"",PEDIDO!AJ36,"") | J11: Pedido 1 | K11: =IF(COUNTIF(PEDIDO!$D$23:$AO$23, K$10)>0, K$10, "") | L11: =IF(COUNTIF(PEDIDO!$D$23:$AO$23, L$10)>0, L$10, "") | M11: =IF(COUNTIF(PEDIDO!$D$23:$AO$23, M$10)>0, M$10, "") | N11: =IF(COUNTIF(PEDIDO!$D$23:$AO$23, N$10)>0, N$10, "") | O11: =IF(COUNTIF(PEDIDO!$D$23:$AO$23, O$10)>0, O$10, "") | P11: =IF(COUNTIF(PEDIDO!$D$23:$AO$23, P$10)>0, P$10, "") | Q11: =IF(COUNTIF(PEDIDO!$D$23:$AO$23, Q$10)>0, Q$10, "") | R11: =IF(COUNTIF(PEDIDO!$D$23:$AO$23, R$10)>0, R$10, "") | ... DV11: =IF(COUNTIF(PEDIDO!$D$23:$AO$23, DV$10)>0, DV$10, "") | DY11: BABUCHE MASCULINO | DZ11: AUTENTICA | EA11: 551 JEANS | EB11: AERORANG | EC11: 360 TO CROSS
A12: =IF(PEDIDO!C37<>"",PEDIDO!B37,"") | B12: =IF(PEDIDO!X37<>"",PEDIDO!X37,"") | C12: =IF(PEDIDO!AA37<>"",PEDIDO!AA37,"") | D12: =IF(PEDIDO!AD37<>"",PEDIDO!AD37,"") | E12: =IF(PEDIDO!AG37<>"",PEDIDO!AG37,"") | F12: =IF(PEDIDO!AJ37<>"",PEDIDO!AJ37,"") | J12: =IF(PEDIDO!C36<>"",PEDIDO!B36,"") | K12: =IF($K$11<>"",B11,"") | L12: =IF($L$11<>"",B11,"") | M12: =IF($M$11<>"",B11,"") | N12: =IF($N$11<>"",B11,"") | O12: =IF($O$11<>"",B11,"") | P12: =IF($P$11<>"",B11,"") | Q12: =IF($Q$11<>"",B11,"") | R12: =IF($R$11<>"",B11,"") | S12: =IF($S$11<>"",B11,"") | T12: =IF($T$11<>"",B11,"") | U12: =IF($U$11<>"",B11,"") | V12: =IF($V$11<>"",B11,"") | W12: =IF($W$11<>"",B11,"") | X12: =IF($X$11<>"",B11,"") | Y12: =IF($Y$11<>"",B11,"") | Z12: =IF($Z$11<>"",B11,"") | AA12: =IF($AA$11<>"",B11,"") | AB12: =IF($AB$11<>"",B11,"") | AC12: =IF($AC$11<>"",B11,"") | AD12: =IF($AD$11<>"",B11,"") | AE12: =IF($AE$11<>"",B11,"") | AF12: =IF($AF$11<>"",B11,"") | AG12: =IF($AG$11<>"",B11,"") | AH12: =IF($AH$11<>"",B11,"") | AI12: =IF($AI$11<>"",B11,"") | AJ12: =IF($AJ$11<>"",B11,"") | AK12: =IF($AK$11<>"",B11,"") | AL12: =IF($AL$11<>"",B11,"") | AM12: =IF($AM$11<>"",B11,"") | AN12: =IF($AN$11<>"",B11,"") | AO12: =IF($AO$11<>"",B11,"") | AP12: =IF($AP$11<>"",B11,"") | AQ12: =IF($AQ$11<>"",B11,"") | AR12: =IF($AR$11<>"",B11,"") | AS12: =IF($AS$11<>"",B11,"") | AT12: =IF($AT$11<>"",B11,"") | AU12: =IF($AU$11<>"",B11,"") | AV12: =IF($AV$11<>"",B11,"") | AW12: =IF($AW$11<>"",B11,"") | AX12: =IF($AX$11<>"",B11,"") | AY12: =IF($AY$11<>"",B11,"") | AZ12: =IF($AZ$11<>"",B11,"") | BA12: =IF($BA$11<>"",B11,"") | BB12: =IF($BB$11<>"",B11,"") | BC12: =IF($BC$11<>"",B11,"") | BD12: =IF($BD$11<>"",B11,"") | BE12: =IF($BE$11<>"",B11,"") | BF12: =IF($BF$11<>"",B11,"") | BG12: =IF($BG$11<>"",B11,"") | BH12: =IF($BH$11<>"",B11,"") | BI12: =IF($BI$11<>"",B11,"") | BJ12: =IF($BJ$11<>"",B11,"") | BK12: =IF($BK$11<>"",B11,"") | BL12: =IF($BL$11<>"",B11,"") | BM12: =IF($BM$11<>"",B11,"") | BN12: =IF($BN$11<>"",B11,"") | BO12: =IF($BO$11<>"",B11,"") | BP12: =IF($BP$11<>"",B11,"") | BQ12: =IF($BQ$11<>"",B11,"") | BR12: =IF($BR$11<>"",B11,"") | BS12: =IF($BS$11<>"",B11,"") | BT12: =IF($BT$11<>"",B11,"") | BU12: =IF($BU$11<>"",B11,"") | BV12: =IF($BV$11<>"",B11,"") | BW12: =IF($BW$11<>"",B11,"") | BX12: =IF($BX$11<>"",B11,"") | BY12: =IF($BY$11<>"",B11,"") | BZ12: =IF($BZ$11<>"",B11,"") | CA12: =IF($CA$11<>"",B11,"") | CB12: =IF($CB$11<>"",B11,"") | CC12: =IF($CC$11<>"",B11,"") | CD12: =IF($CD$11<>"",B11,"") | CE12: =IF($CE$11<>"",B11,"") | CF12: =IF($CF$11<>"",B11,"") | CG12: =IF($CG$11<>"",B11,"") | CH12: =IF($CH$11<>"",B11,"") | CI12: =IF($CI$11<>"",B11,"") | CJ12: =IF($CJ$11<>"",B11,"") | CK12: =IF($CK$11<>"",B11,"") | CL12: =IF($CL$11<>"",B11,"") | CM12: =IF($CM$11<>"",B11,"") | CN12: =IF($CN$11<>"",B11,"") | CO12: =IF($CO$11<>"",B11,"") | CP12: =IF($CP$11<>"",B11,"") | CQ12: =IF($CQ$11<>"",B11,"") | CR12: =IF($CR$11<>"",B11,"") | CS12: =IF($CS$11<>"",B11,"") | CT12: =IF($CT$11<>"",B11,"") | CU12: =IF($CU$11<>"",B11,"") | CV12: =IF($CV$11<>"",B11,"") | CW12: =IF($CW$11<>"",B11,"") | CX12: =IF($CX$11<>"",B11,"") | CY12: =IF($CY$11<>"",B11,"") | CZ12: =IF($CZ$11<>"",B11,"") | DA12: =IF($DA$11<>"",B11,"") | DB12: =IF($DB$11<>"",B11,"") | DC12: =IF($DC$11<>"",B11,"") | DD12: =IF($DD$11<>"",B11,"") | DE12: =IF($DE$11<>"",B11,"") | DF12: =IF($DF$11<>"",B11,"") | DG12: =IF($DG$11<>"",B11,"") | DH12: =IF($DH$11<>"",B11,"") | DI12: =IF($DI$11<>"",B11,"") | DJ12: =IF($DJ$11<>"",B11,"") | DK12: =IF($DK$11<>"",$B11,"") | DL12: =IF($DL$11<>"",$B11,"") | DM12: =IF($DM$11<>"",$B11,"") | DN12: =IF($DN$11<>"",$B11,"") | DO12: =IF($DO$11<>"",$B11,"") | DP12: =IF($DP$11<>"",$B11,"") | DQ12: =IF($DQ$11<>"",$B11,"") | DR12: =IF($DR$11<>"",$B11,"") | DS12: =IF($DS$11<>"",$B11,"") | DT12: =IF($DT$11<>"",$B11,"") | DU12: =IF($DU$11<>"",$B11,"") | DV12: =IF($DV$11<>"",$B11,"") | DY12: BABY DOLL | DZ12: DUFRIO | EA12: 7 SEVEN | EB12: ALECRIM | EC12: 360 TO FLY
A13: =IF(PEDIDO!C38<>"",PEDIDO!B38,"") | B13: =IF(PEDIDO!X38<>"",PEDIDO!X38,"") | C13: =IF(PEDIDO!AA38<>"",PEDIDO!AA38,"") | D13: =IF(PEDIDO!AD38<>"",PEDIDO!AD38,"") | E13: =IF(PEDIDO!AG38<>"",PEDIDO!AG38,"") | F13: =IF(PEDIDO!AJ38<>"",PEDIDO!AJ38,"") | J13: =IF(PEDIDO!C37<>"",PEDIDO!B37,"") | K13: =IF($K$11<>"",B12,"") | L13: =IF($L$11<>"",B12,"") | M13: =IF($M$11<>"",B12,"") | N13: =IF($N$11<>"",B12,"") | O13: =IF($O$11<>"",B12,"") | P13: =IF($P$11<>"",B12,"") | Q13: =IF($Q$11<>"",B12,"") | R13: =IF($R$11<>"",B12,"") | S13: =IF($S$11<>"",B12,"") | T13: =IF($T$11<>"",B12,"") | U13: =IF($U$11<>"",B12,"") | V13: =IF($V$11<>"",B12,"") | W13: =IF($W$11<>"",B12,"") | X13: =IF($X$11<>"",B12,"") | Y13: =IF($Y$11<>"",B12,"") | Z13: =IF($Z$11<>"",B12,"") | AA13: =IF($AA$11<>"",B12,"") | AB13: =IF($AB$11<>"",B12,"") | AC13: =IF($AC$11<>"",B12,"") | AD13: =IF($AD$11<>"",B12,"") | AE13: =IF($AE$11<>"",B12,"") | AF13: =IF($AF$11<>"",B12,"") | AG13: =IF($AG$11<>"",B12,"") | AH13: =IF($AH$11<>"",B12,"") | AI13: =IF($AI$11<>"",B12,"") | AJ13: =IF($AJ$11<>"",B12,"") | AK13: =IF($AK$11<>"",B12,"") | AL13: =IF($AL$11<>"",B12,"") | AM13: =IF($AM$11<>"",B12,"") | AN13: =IF($AN$11<>"",B12,"") | AO13: =IF($AO$11<>"",B12,"") | AP13: =IF($AP$11<>"",B12,"") | AQ13: =IF($AQ$11<>"",B12,"") | AR13: =IF($AR$11<>"",B12,"") | AS13: =IF($AS$11<>"",B12,"") | AT13: =IF($AT$11<>"",B12,"") | AU13: =IF($AU$11<>"",B12,"") | AV13: =IF($AV$11<>"",B12,"") | AW13: =IF($AW$11<>"",B12,"") | AX13: =IF($AX$11<>"",B12,"") | AY13: =IF($AY$11<>"",B12,"") | AZ13: =IF($AZ$11<>"",B12,"") | BA13: =IF($BA$11<>"",B12,"") | BB13: =IF($BB$11<>"",B12,"") | BC13: =IF($BC$11<>"",B12,"") | BD13: =IF($BD$11<>"",B12,"") | BE13: =IF($BE$11<>"",B12,"") | BF13: =IF($BF$11<>"",B12,"") | BG13: =IF($BG$11<>"",B12,"") | BH13: =IF($BH$11<>"",B12,"") | BI13: =IF($BI$11<>"",B12,"") | BJ13: =IF($BJ$11<>"",B12,"") | BK13: =IF($BK$11<>"",B12,"") | BL13: =IF($BL$11<>"",B12,"") | BM13: =IF($BM$11<>"",B12,"") | BN13: =IF($BN$11<>"",B12,"") | BO13: =IF($BO$11<>"",B12,"") | BP13: =IF($BP$11<>"",B12,"") | BQ13: =IF($BQ$11<>"",B12,"") | BR13: =IF($BR$11<>"",B12,"") | BS13: =IF($BS$11<>"",B12,"") | BT13: =IF($BT$11<>"",B12,"") | BU13: =IF($BU$11<>"",B12,"") | BV13: =IF($BV$11<>"",B12,"") | BW13: =IF($BW$11<>"",B12,"") | BX13: =IF($BX$11<>"",B12,"") | BY13: =IF($BY$11<>"",B12,"") | BZ13: =IF($BZ$11<>"",B12,"") | CA13: =IF($CA$11<>"",B12,"") | CB13: =IF($CB$11<>"",B12,"") | CC13: =IF($CC$11<>"",B12,"") | CD13: =IF($CD$11<>"",B12,"") | CE13: =IF($CE$11<>"",B12,"") | CF13: =IF($CF$11<>"",B12,"") | CG13: =IF($CG$11<>"",B12,"") | CH13: =IF($CH$11<>"",B12,"") | CI13: =IF($CI$11<>"",B12,"") | CJ13: =IF($CJ$11<>"",B12,"") | CK13: =IF($CK$11<>"",B12,"") | CL13: =IF($CL$11<>"",B12,"") | CM13: =IF($CM$11<>"",B12,"") | CN13: =IF($CN$11<>"",B12,"") | CO13: =IF($CO$11<>"",B12,"") | CP13: =IF($CP$11<>"",B12,"") | CQ13: =IF($CQ$11<>"",B12,"") | CR13: =IF($CR$11<>"",B12,"") | CS13: =IF(CS12<>"",$B$12,"") | CT13: =IF($CT$11<>"",B12,"") | CU13: =IF($CU$11<>"",B12,"") | CV13: =IF($CV$11<>"",B12,"") | CW13: =IF($CW$11<>"",B12,"") | CX13: =IF($CX$11<>"",B12,"") | CY13: =IF($CY$11<>"",B12,"") | CZ13: =IF($CZ$11<>"",B12,"") | DA13: =IF($DA$11<>"",B12,"") | DB13: =IF($DB$11<>"",B12,"") | DC13: =IF($DC$11<>"",B12,"") | DD13: =IF($DD$11<>"",B12,"") | DE13: =IF($DE$11<>"",B12,"") | DF13: =IF($DF$11<>"",B12,"") | DG13: =IF($DG$11<>"",B12,"") | DH13: =IF($DH$11<>"",B12,"") | DI13: =IF($DI$11<>"",B12,"") | DJ13: =IF($DJ$11<>"",B12,"") | DK13: =IF($DK$11<>"",$B12,"") | DL13: =IF($DL$11<>"",$B12,"") | DM13: =IF($DM$11<>"",$B12,"") | DN13: =IF($DN$11<>"",$B12,"") | DO13: =IF($DO$11<>"",$B12,"") | DP13: =IF($DP$11<>"",$B12,"") | DQ13: =IF($DQ$11<>"",$B12,"") | DR13: =IF($DR$11<>"",$B12,"") | DS13: =IF($DS$11<>"",$B12,"") | DT13: =IF($DT$11<>"",$B12,"") | DU13: =IF($DU$11<>"",$B12,"") | DV13: =IF($DV$11<>"",$B12,"") | DY13: BABY DOLL FEMININO | DZ13: KEROLYNE | EA13: 767 JEANS | EB13: ALFAZEMA | EC13: 360 TO GO
A14: =IF(PEDIDO!C39<>"",PEDIDO!B39,"") | B14: =IF(PEDIDO!X39<>"",PEDIDO!X39,"") | C14: =IF(PEDIDO!AA39<>"",PEDIDO!AA39,"") | D14: =IF(PEDIDO!AD39<>"",PEDIDO!AD39,"") | E14: =IF(PEDIDO!AG39<>"",PEDIDO!AG39,"") | F14: =IF(PEDIDO!AJ39<>"",PEDIDO!AJ39,"") | J14: =IF(PEDIDO!C38<>"",PEDIDO!B38,"") | K14: =IF($K$11<>"",B13,"") | L14: =IF($L$11<>"",B13,"") | M14: =IF($M$11<>"",B13,"") | N14: =IF($N$11<>"",B13,"") | O14: =IF($O$11<>"",B13,"") | P14: =IF($P$11<>"",B13,"") | Q14: =IF($Q$11<>"",B13,"") | R14: =IF($R$11<>"",B13,"") | S14: =IF($S$11<>"",B13,"") | T14: =IF($T$11<>"",B13,"") | U14: =IF($U$11<>"",B13,"") | V14: =IF($V$11<>"",B13,"") | W14: =IF($W$11<>"",B13,"") | X14: =IF($X$11<>"",B13,"") | Y14: =IF($Y$11<>"",B13,"") | Z14: =IF($Z$11<>"",B13,"") | AA14: =IF($AA$11<>"",B13,"") | AB14: =IF($AB$11<>"",B13,"") | AC14: =IF($AC$11<>"",B13,"") | AD14: =IF($AD$11<>"",B13,"") | AE14: =IF($AE$11<>"",B13,"") | AF14: =IF($AF$11<>"",B13,"") | AG14: =IF($AG$11<>"",B13,"") | AH14: =IF($AH$11<>"",B13,"") | AI14: =IF($AI$11<>"",B13,"") | AJ14: =IF($AJ$11<>"",B13,"") | AK14: =IF($AK$11<>"",B13,"") | AL14: =IF($AL$11<>"",B13,"") | AM14: =IF($AM$11<>"",B13,"") | AN14: =IF($AN$11<>"",B13,"") | AO14: =IF($AO$11<>"",B13,"") | AP14: =IF($AP$11<>"",B13,"") | AQ14: =IF($AQ$11<>"",B13,"") | AR14: =IF($AR$11<>"",B13,"") | AS14: =IF($AS$11<>"",B13,"") | AT14: =IF($AT$11<>"",B13,"") | AU14: =IF($AU$11<>"",B13,"") | AV14: =IF($AV$11<>"",B13,"") | AW14: =IF($AW$11<>"",B13,"") | AX14: =IF($AX$11<>"",B13,"") | AY14: =IF($AY$11<>"",B13,"") | AZ14: =IF($AZ$11<>"",B13,"") | BA14: =IF($BA$11<>"",B13,"") | BB14: =IF($BB$11<>"",B13,"") | BC14: =IF($BC$11<>"",B13,"") | BD14: =IF($BD$11<>"",B13,"") | BE14: =IF($BE$11<>"",B13,"") | BF14: =IF($BF$11<>"",B13,"") | BG14: =IF($BG$11<>"",B13,"") | BH14: =IF($BH$11<>"",B13,"") | BI14: =IF($BI$11<>"",B13,"") | BJ14: =IF($BJ$11<>"",B13,"") | BK14: =IF($BK$11<>"",B13,"") | BL14: =IF($BL$11<>"",B13,"") | BM14: =IF($BM$11<>"",B13,"") | BN14: =IF($BN$11<>"",B13,"") | BO14: =IF($BO$11<>"",B13,"") | BP14: =IF($BP$11<>"",B13,"") | BQ14: =IF($BQ$11<>"",B13,"") | BR14: =IF($BR$11<>"",B13,"") | BS14: =IF($BS$11<>"",B13,"") | BT14: =IF($BT$11<>"",B13,"") | BU14: =IF($BU$11<>"",B13,"") | BV14: =IF($BV$11<>"",B13,"") | BW14: =IF($BW$11<>"",B13,"") | BX14: =IF($BX$11<>"",B13,"") | BY14: =IF($BY$11<>"",B13,"") | BZ14: =IF($BZ$11<>"",B13,"") | CA14: =IF($CA$11<>"",B13,"") | CB14: =IF($CB$11<>"",B13,"") | CC14: =IF($CC$11<>"",B13,"") | CD14: =IF($CD$11<>"",B13,"") | CE14: =IF($CE$11<>"",B13,"") | CF14: =IF($CF$11<>"",B13,"") | CG14: =IF($CG$11<>"",B13,"") | CH14: =IF($CH$11<>"",B13,"") | CI14: =IF($CI$11<>"",B13,"") | CJ14: =IF($CJ$11<>"",B13,"") | CK14: =IF($CK$11<>"",B13,"") | CL14: =IF($CL$11<>"",B13,"") | CM14: =IF($CM$11<>"",B13,"") | CN14: =IF($CN$11<>"",B13,"") | CO14: =IF($CO$11<>"",B13,"") | CP14: =IF($CP$11<>"",B13,"") | CQ14: =IF($CQ$11<>"",B13,"") | CR14: =IF($CR$11<>"",B13,"") | CS14: =IF(CS13<>"",$B$13,"") | CT14: =IF($CT$11<>"",B13,"") | CU14: =IF($CU$11<>"",B13,"") | CV14: =IF($CV$11<>"",B13,"") | CW14: =IF($CW$11<>"",B13,"") | CX14: =IF($CX$11<>"",B13,"") | CY14: =IF($CY$11<>"",B13,"") | CZ14: =IF($CZ$11<>"",B13,"") | DA14: =IF($DA$11<>"",B13,"") | DB14: =IF($DB$11<>"",B13,"") | DC14: =IF($DC$11<>"",B13,"") | DD14: =IF($DD$11<>"",B13,"") | DE14: =IF($DE$11<>"",B13,"") | DF14: =IF($DF$11<>"",B13,"") | DG14: =IF($DG$11<>"",B13,"") | DH14: =IF($DH$11<>"",B13,"") | DI14: =IF($DI$11<>"",B13,"") | DJ14: =IF($DJ$11<>"",B13,"") | DK14: =IF($DK$11<>"",$B13,"") | DL14: =IF($DL$11<>"",$B13,"") | DM14: =IF($DM$11<>"",$B13,"") | DN14: =IF($DN$11<>"",$B13,"") | DO14: =IF($DO$11<>"",$B13,"") | DP14: =IF($DP$11<>"",$B13,"") | DQ14: =IF($DQ$11<>"",$B13,"") | DR14: =IF($DR$11<>"",$B13,"") | DS14: =IF($DS$11<>"",$B13,"") | DT14: =IF($DT$11<>"",$B13,"") | DU14: =IF($DU$11<>"",$B13,"") | DV14: =IF($DV$11<>"",$B13,"") | DY14: BABY LOOK | DZ14: SYSTEM32 | EA14: A E | EB14: ALGA | EC14: 360 TO TRAVEL
A15: =IF(PEDIDO!C40<>"",PEDIDO!B40,"") | B15: =IF(PEDIDO!X40<>"",PEDIDO!X40,"") | C15: =IF(PEDIDO!AA40<>"",PEDIDO!AA40,"") | D15: =IF(PEDIDO!AD40<>"",PEDIDO!AD40,"") | E15: =IF(PEDIDO!AG40<>"",PEDIDO!AG40,"") | F15: =IF(PEDIDO!AJ40<>"",PEDIDO!AJ40,"") | J15: =IF(PEDIDO!C39<>"",PEDIDO!B39,"") | K15: =IF($K$11<>"",B14,"") | L15: =IF($L$11<>"",B14,"") | M15: =IF($M$11<>"",B14,"") | N15: =IF($N$11<>"",B14,"") | O15: =IF($O$11<>"",B14,"") | P15: =IF($P$11<>"",B14,"") | Q15: =IF($Q$11<>"",B14,"") | R15: =IF($R$11<>"",B14,"") | S15: =IF($S$11<>"",B14,"") | T15: =IF($T$11<>"",B14,"") | U15: =IF($U$11<>"",B14,"") | V15: =IF($V$11<>"",B14,"") | W15: =IF($W$11<>"",B14,"") | X15: =IF($X$11<>"",B14,"") | Y15: =IF($Y$11<>"",B14,"") | Z15: =IF($Z$11<>"",B14,"") | AA15: =IF($AA$11<>"",B14,"") | AB15: =IF($AB$11<>"",B14,"") | AC15: =IF($AC$11<>"",B14,"") | AD15: =IF($AD$11<>"",B14,"") | AE15: =IF($AE$11<>"",B14,"") | AF15: =IF($AF$11<>"",B14,"") | AG15: =IF($AG$11<>"",B14,"") | AH15: =IF($AH$11<>"",B14,"") | AI15: =IF($AI$11<>"",B14,"") | AJ15: =IF($AJ$11<>"",B14,"") | AK15: =IF($AK$11<>"",B14,"") | AL15: =IF($AL$11<>"",B14,"") | AM15: =IF($AM$11<>"",B14,"") | AN15: =IF($AN$11<>"",B14,"") | AO15: =IF($AO$11<>"",B14,"") | AP15: =IF($AP$11<>"",B14,"") | AQ15: =IF($AQ$11<>"",B14,"") | AR15: =IF($AR$11<>"",B14,"") | AS15: =IF($AS$11<>"",B14,"") | AT15: =IF($AT$11<>"",B14,"") | AU15: =IF($AU$11<>"",B14,"") | AV15: =IF($AV$11<>"",B14,"") | AW15: =IF($AW$11<>"",B14,"") | AX15: =IF($AX$11<>"",B14,"") | AY15: =IF($AY$11<>"",B14,"") | AZ15: =IF($AZ$11<>"",B14,"") | BA15: =IF($BA$11<>"",B14,"") | BB15: =IF($BB$11<>"",B14,"") | BC15: =IF($BC$11<>"",B14,"") | BD15: =IF($BD$11<>"",B14,"") | BE15: =IF($BE$11<>"",B14,"") | BF15: =IF($BF$11<>"",B14,"") | BG15: =IF($BG$11<>"",B14,"") | BH15: =IF($BH$11<>"",B14,"") | BI15: =IF($BI$11<>"",B14,"") | BJ15: =IF($BJ$11<>"",B14,"") | BK15: =IF($BK$11<>"",B14,"") | BL15: =IF($BL$11<>"",B14,"") | BM15: =IF($BM$11<>"",B14,"") | BN15: =IF($BN$11<>"",B14,"") | BO15: =IF($BO$11<>"",B14,"") | BP15: =IF($BP$11<>"",B14,"") | BQ15: =IF($BQ$11<>"",B14,"") | BR15: =IF($BR$11<>"",B14,"") | BS15: =IF($BS$11<>"",B14,"") | BT15: =IF($BT$11<>"",B14,"") | BU15: =IF($BU$11<>"",B14,"") | BV15: =IF($BV$11<>"",B14,"") | BW15: =IF($BW$11<>"",B14,"") | BX15: =IF($BX$11<>"",B14,"") | BY15: =IF($BY$11<>"",B14,"") | BZ15: =IF($BZ$11<>"",B14,"") | CA15: =IF($CA$11<>"",B14,"") | CB15: =IF($CB$11<>"",B14,"") | CC15: =IF($CC$11<>"",B14,"") | CD15: =IF($CD$11<>"",B14,"") | CE15: =IF($CE$11<>"",B14,"") | CF15: =IF($CF$11<>"",B14,"") | CG15: =IF($CG$11<>"",B14,"") | CH15: =IF($CH$11<>"",B14,"") | CI15: =IF($CI$11<>"",B14,"") | CJ15: =IF($CJ$11<>"",B14,"") | CK15: =IF($CK$11<>"",B14,"") | CL15: =IF($CL$11<>"",B14,"") | CM15: =IF($CM$11<>"",B14,"") | CN15: =IF($CN$11<>"",B14,"") | CO15: =IF($CO$11<>"",B14,"") | CP15: =IF($CP$11<>"",B14,"") | CQ15: =IF($CQ$11<>"",B14,"") | CR15: =IF($CR$11<>"",B14,"") | CS15: =IF(CS14<>"",$B$14,"") | CT15: =IF($CT$11<>"",B14,"") | CU15: =IF($CU$11<>"",B14,"") | CV15: =IF($CV$11<>"",B14,"") | CW15: =IF($CW$11<>"",B14,"") | CX15: =IF($CX$11<>"",B14,"") | CY15: =IF($CY$11<>"",B14,"") | CZ15: =IF($CZ$11<>"",B14,"") | DA15: =IF($DA$11<>"",B14,"") | DB15: =IF($DB$11<>"",B14,"") | DC15: =IF($DC$11<>"",B14,"") | DD15: =IF($DD$11<>"",B14,"") | DE15: =IF($DE$11<>"",B14,"") | DF15: =IF($DF$11<>"",B14,"") | DG15: =IF($DG$11<>"",B14,"") | DH15: =IF($DH$11<>"",B14,"") | DI15: =IF($DI$11<>"",B14,"") | DJ15: =IF($DJ$11<>"",B14,"") | DK15: =IF($DK$11<>"",$B14,"") | DL15: =IF($DL$11<>"",$B14,"") | DM15: =IF($DM$11<>"",$B14,"") | DN15: =IF($DN$11<>"",$B14,"") | DO15: =IF($DO$11<>"",$B14,"") | DP15: =IF($DP$11<>"",$B14,"") | DQ15: =IF($DQ$11<>"",$B14,"") | DR15: =IF($DR$11<>"",$B14,"") | DS15: =IF($DS$11<>"",$B14,"") | DT15: =IF($DT$11<>"",$B14,"") | DU15: =IF($DU$11<>"",$B14,"") | DV15: =IF($DV$11<>"",$B14,"") | DY15: BABY LOOK INFANTIL | DZ15: BAHIA | EA15: A F FELIPE | EB15: ALGIERS BLUE | EC15: 360 TO WALK
A16: =IF(PEDIDO!C41<>"",PEDIDO!B41,"") | B16: =IF(PEDIDO!X41<>"",PEDIDO!X41,"") | C16: =IF(PEDIDO!AA41<>"",PEDIDO!AA41,"") | D16: =IF(PEDIDO!AD41<>"",PEDIDO!AD41,"") | E16: =IF(PEDIDO!AG41<>"",PEDIDO!AG41,"") | F16: =IF(PEDIDO!AJ41<>"",PEDIDO!AJ41,"") | J16: =IF(PEDIDO!C40<>"",PEDIDO!B40,"") | K16: =IF($K$11<>"",B15,"") | L16: =IF($L$11<>"",B15,"") | M16: =IF($M$11<>"",B15,"") | N16: =IF($N$11<>"",B15,"") | O16: =IF($O$11<>"",B15,"") | P16: =IF($P$11<>"",B15,"") | Q16: =IF($Q$11<>"",B15,"") | R16: =IF($R$11<>"",B15,"") | S16: =IF($S$11<>"",B15,"") | T16: =IF($T$11<>"",B15,"") | U16: =IF($U$11<>"",B15,"") | V16: =IF($V$11<>"",B15,"") | W16: =IF($W$11<>"",B15,"") | X16: =IF($X$11<>"",B15,"") | Y16: =IF($Y$11<>"",B15,"") | Z16: =IF($Z$11<>"",B15,"") | AA16: =IF($AA$11<>"",B15,"") | AB16: =IF($AB$11<>"",B15,"") | AC16: =IF($AC$11<>"",B15,"") | AD16: =IF($AD$11<>"",B15,"") | AE16: =IF($AE$11<>"",B15,"") | AF16: =IF($AF$11<>"",B15,"") | AG16: =IF($AG$11<>"",B15,"") | AH16: =IF($AH$11<>"",B15,"") | AI16: =IF($AI$11<>"",B15,"") | AJ16: =IF($AJ$11<>"",B15,"") | AK16: =IF($AK$11<>"",B15,"") | AL16: =IF($AL$11<>"",B15,"") | AM16: =IF($AM$11<>"",B15,"") | AN16: =IF($AN$11<>"",B15,"") | AO16: =IF($AO$11<>"",B15,"") | AP16: =IF($AP$11<>"",B15,"") | AQ16: =IF($AQ$11<>"",B15,"") | AR16: =IF($AR$11<>"",B15,"") | AS16: =IF($AS$11<>"",B15,"") | AT16: =IF($AT$11<>"",B15,"") | AU16: =IF($AU$11<>"",B15,"") | AV16: =IF($AV$11<>"",B15,"") | AW16: =IF($AW$11<>"",B15,"") | AX16: =IF($AX$11<>"",B15,"") | AY16: =IF($AY$11<>"",B15,"") | AZ16: =IF($AZ$11<>"",B15,"") | BA16: =IF($BA$11<>"",B15,"") | BB16: =IF($BB$11<>"",B15,"") | BC16: =IF($BC$11<>"",B15,"") | BD16: =IF($BD$11<>"",B15,"") | BE16: =IF($BE$11<>"",B15,"") | BF16: =IF($BF$11<>"",B15,"") | BG16: =IF($BG$11<>"",B15,"") | BH16: =IF($BH$11<>"",B15,"") | BI16: =IF($BI$11<>"",B15,"") | BJ16: =IF($BJ$11<>"",B15,"") | BK16: =IF($BK$11<>"",B15,"") | BL16: =IF($BL$11<>"",B15,"") | BM16: =IF($BM$11<>"",B15,"") | BN16: =IF($BN$11<>"",B15,"") | BO16: =IF($BO$11<>"",B15,"") | BP16: =IF($BP$11<>"",B15,"") | BQ16: =IF($BQ$11<>"",B15,"") | BR16: =IF($BR$11<>"",B15,"") | BS16: =IF($BS$11<>"",B15,"") | BT16: =IF($BT$11<>"",B15,"") | BU16: =IF($BU$11<>"",B15,"") | BV16: =IF($BV$11<>"",B15,"") | BW16: =IF($BW$11<>"",B15,"") | BX16: =IF($BX$11<>"",B15,"") | BY16: =IF($BY$11<>"",B15,"") | BZ16: =IF($BZ$11<>"",B15,"") | CA16: =IF($CA$11<>"",B15,"") | CB16: =IF($CB$11<>"",B15,"") | CC16: =IF($CC$11<>"",B15,"") | CD16: =IF($CD$11<>"",B15,"") | CE16: =IF($CE$11<>"",B15,"") | CF16: =IF($CF$11<>"",B15,"") | CG16: =IF($CG$11<>"",B15,"") | CH16: =IF($CH$11<>"",B15,"") | CI16: =IF($CI$11<>"",B15,"") | CJ16: =IF($CJ$11<>"",B15,"") | CK16: =IF($CK$11<>"",B15,"") | CL16: =IF($CL$11<>"",B15,"") | CM16: =IF($CM$11<>"",B15,"") | CN16: =IF($CN$11<>"",B15,"") | CO16: =IF($CO$11<>"",B15,"") | CP16: =IF($CP$11<>"",B15,"") | CQ16: =IF($CQ$11<>"",B15,"") | CR16: =IF($CR$11<>"",B15,"") | CS16: =IF(CS15<>"",$B$15,"") | CT16: =IF($CT$11<>"",B15,"") | CU16: =IF($CU$11<>"",B15,"") | CV16: =IF($CV$11<>"",B15,"") | CW16: =IF($CW$11<>"",B15,"") | CX16: =IF($CX$11<>"",B15,"") | CY16: =IF($CY$11<>"",B15,"") | CZ16: =IF($CZ$11<>"",B15,"") | DA16: =IF($DA$11<>"",B15,"") | DB16: =IF($DB$11<>"",B15,"") | DC16: =IF($DC$11<>"",B15,"") | DD16: =IF($DD$11<>"",B15,"") | DE16: =IF($DE$11<>"",B15,"") | DF16: =IF($DF$11<>"",B15,"") | DG16: =IF($DG$11<>"",B15,"") | DH16: =IF($DH$11<>"",B15,"") | DI16: =IF($DI$11<>"",B15,"") | DJ16: =IF($DJ$11<>"",B15,"") | DK16: =IF($DK$11<>"",$B15,"") | DL16: =IF($DL$11<>"",$B15,"") | DM16: =IF($DM$11<>"",$B15,"") | DN16: =IF($DN$11<>"",$B15,"") | DO16: =IF($DO$11<>"",$B15,"") | DP16: =IF($DP$11<>"",$B15,"") | DQ16: =IF($DQ$11<>"",$B15,"") | DR16: =IF($DR$11<>"",$B15,"") | DS16: =IF($DS$11<>"",$B15,"") | DT16: =IF($DT$11<>"",$B15,"") | DU16: =IF($DU$11<>"",$B15,"") | DV16: =IF($DV$11<>"",$B15,"") | DY16: BAG | DZ16: NEW BALANCE | EA16: A PÉ | EB16: ALGODAO | EC16: 360 ZAFIRA 2T
A17: =IF(PEDIDO!C42<>"",PEDIDO!B42,"") | B17: =IF(PEDIDO!X42<>"",PEDIDO!X42,"") | C17: =IF(PEDIDO!AA42<>"",PEDIDO!AA42,"") | D17: =IF(PEDIDO!AD42<>"",PEDIDO!AD42,"") | E17: =IF(PEDIDO!AG42<>"",PEDIDO!AG42,"") | F17: =IF(PEDIDO!AJ42<>"",PEDIDO!AJ42,"") | J17: =IF(PEDIDO!C41<>"",PEDIDO!B41,"") | K17: =IF($K$11<>"",B16,"") | L17: =IF($L$11<>"",B16,"") | M17: =IF($M$11<>"",B16,"") | N17: =IF($N$11<>"",B16,"") | O17: =IF($O$11<>"",B16,"") | P17: =IF($P$11<>"",B16,"") | Q17: =IF($Q$11<>"",B16,"") | R17: =IF($R$11<>"",B16,"") | S17: =IF($S$11<>"",B16,"") | T17: =IF($T$11<>"",B16,"") | U17: =IF($U$11<>"",B16,"") | V17: =IF($V$11<>"",B16,"") | W17: =IF($W$11<>"",B16,"") | X17: =IF($X$11<>"",B16,"") | Y17: =IF($Y$11<>"",B16,"") | Z17: =IF($Z$11<>"",B16,"") | AA17: =IF($AA$11<>"",B16,"") | AB17: =IF($AB$11<>"",B16,"") | AC17: =IF($AC$11<>"",B16,"") | AD17: =IF($AD$11<>"",B16,"") | AE17: =IF($AE$11<>"",B16,"") | AF17: =IF($AF$11<>"",B16,"") | AG17: =IF($AG$11<>"",B16,"") | AH17: =IF($AH$11<>"",B16,"") | AI17: =IF($AI$11<>"",B16,"") | AJ17: =IF($AJ$11<>"",B16,"") | AK17: =IF($AK$11<>"",B16,"") | AL17: =IF($AL$11<>"",B16,"") | AM17: =IF($AM$11<>"",B16,"") | AN17: =IF($AN$11<>"",B16,"") | AO17: =IF($AO$11<>"",B16,"") | AP17: =IF($AP$11<>"",B16,"") | AQ17: =IF($AQ$11<>"",B16,"") | AR17: =IF($AR$11<>"",B16,"") | AS17: =IF($AS$11<>"",B16,"") | AT17: =IF($AT$11<>"",B16,"") | AU17: =IF($AU$11<>"",B16,"") | AV17: =IF($AV$11<>"",B16,"") | AW17: =IF($AW$11<>"",B16,"") | AX17: =IF($AX$11<>"",B16,"") | AY17: =IF($AY$11<>"",B16,"") | AZ17: =IF($AZ$11<>"",B16,"") | BA17: =IF($BA$11<>"",B16,"") | BB17: =IF($BB$11<>"",B16,"") | BC17: =IF($BC$11<>"",B16,"") | BD17: =IF($BD$11<>"",B16,"") | BE17: =IF($BE$11<>"",B16,"") | BF17: =IF($BF$11<>"",B16,"") | BG17: =IF($BG$11<>"",B16,"") | BH17: =IF($BH$11<>"",B16,"") | BI17: =IF($BI$11<>"",B16,"") | BJ17: =IF($BJ$11<>"",B16,"") | BK17: =IF($BK$11<>"",B16,"") | BL17: =IF($BL$11<>"",B16,"") | BM17: =IF($BM$11<>"",B16,"") | BN17: =IF($BN$11<>"",B16,"") | BO17: =IF($BO$11<>"",B16,"") | BP17: =IF($BP$11<>"",B16,"") | BQ17: =IF($BQ$11<>"",B16,"") | BR17: =IF($BR$11<>"",B16,"") | BS17: =IF($BS$11<>"",B16,"") | BT17: =IF($BT$11<>"",B16,"") | BU17: =IF($BU$11<>"",B16,"") | BV17: =IF($BV$11<>"",B16,"") | BW17: =IF($BW$11<>"",B16,"") | BX17: =IF($BX$11<>"",B16,"") | BY17: =IF($BY$11<>"",B16,"") | BZ17: =IF($BZ$11<>"",B16,"") | CA17: =IF($CA$11<>"",B16,"") | CB17: =IF($CB$11<>"",B16,"") | CC17: =IF($CC$11<>"",B16,"") | CD17: =IF($CD$11<>"",B16,"") | CE17: =IF($CE$11<>"",B16,"") | CF17: =IF($CF$11<>"",B16,"") | CG17: =IF($CG$11<>"",B16,"") | CH17: =IF($CH$11<>"",B16,"") | CI17: =IF($CI$11<>"",B16,"") | CJ17: =IF($CJ$11<>"",B16,"") | CK17: =IF($CK$11<>"",B16,"") | CL17: =IF($CL$11<>"",B16,"") | CM17: =IF($CM$11<>"",B16,"") | CN17: =IF($CN$11<>"",B16,"") | CO17: =IF($CO$11<>"",B16,"") | CP17: =IF($CP$11<>"",B16,"") | CQ17: =IF($CQ$11<>"",B16,"") | CR17: =IF($CR$11<>"",B16,"") | CS17: =IF(CS16<>"",B$16,"") | CT17: =IF($CT$11<>"",B16,"") | CU17: =IF($CU$11<>"",B16,"") | CV17: =IF($CV$11<>"",B16,"") | CW17: =IF($CW$11<>"",B16,"") | CX17: =IF($CX$11<>"",B16,"") | CY17: =IF($CY$11<>"",B16,"") | CZ17: =IF($CZ$11<>"",B16,"") | DA17: =IF($DA$11<>"",B16,"") | DB17: =IF($DB$11<>"",B16,"") | DC17: =IF($DC$11<>"",B16,"") | DD17: =IF($DD$11<>"",B16,"") | DE17: =IF($DE$11<>"",B16,"") | DF17: =IF($DF$11<>"",B16,"") | DG17: =IF($DG$11<>"",B16,"") | DH17: =IF($DH$11<>"",B16,"") | DI17: =IF($DI$11<>"",B16,"") | DJ17: =IF($DJ$11<>"",B16,"") | DK17: =IF($DK$11<>"",$B16,"") | DL17: =IF($DL$11<>"",$B16,"") | DM17: =IF($DM$11<>"",$B16,"") | DN17: =IF($DN$11<>"",$B16,"") | DO17: =IF($DO$11<>"",$B16,"") | DP17: =IF($DP$11<>"",$B16,"") | DQ17: =IF($DQ$11<>"",$B16,"") | DR17: =IF($DR$11<>"",$B16,"") | DS17: =IF($DS$11<>"",$B16,"") | DT17: =IF($DT$11<>"",$B16,"") | DU17: =IF($DU$11<>"",$B16,"") | DV17: =IF($DV$11<>"",$B16,"") | DY17: BANCO | DZ17: SOCIALLE | EA17: A&E | EB17: ALIGATOR | EC17: 360 ZIGMA
A18: =IF(PEDIDO!C43<>"",PEDIDO!B43,"") | B18: =IF(PEDIDO!X43<>"",PEDIDO!X43,"") | C18: =IF(PEDIDO!AA43<>"",PEDIDO!AA43,"") | D18: =IF(PEDIDO!AD43<>"",PEDIDO!AD43,"") | E18: =IF(PEDIDO!AG43<>"",PEDIDO!AG43,"") | F18: =IF(PEDIDO!AJ43<>"",PEDIDO!AJ43,"") | J18: =IF(PEDIDO!C42<>"",PEDIDO!B42,"") | K18: =IF($K$11<>"",B17,"") | L18: =IF($L$11<>"",B17,"") | M18: =IF($M$11<>"",B17,"") | N18: =IF($N$11<>"",B17,"") | O18: =IF($O$11<>"",B17,"") | P18: =IF($P$11<>"",B17,"") | Q18: =IF($Q$11<>"",B17,"") | R18: =IF($R$11<>"",B17,"") | S18: =IF($S$11<>"",B17,"") | T18: =IF($T$11<>"",B17,"") | U18: =IF($U$11<>"",B17,"") | V18: =IF($V$11<>"",B17,"") | X18: =IF($X$11<>"",B17,"") | Y18: =IF($Y$11<>"",B17,"") | Z18: =IF($Z$11<>"",B17,"") | AA18: =IF($AA$11<>"",B17,"") | AB18: =IF($AB$11<>"",B17,"") | AC18: =IF($AC$11<>"",B17,"") | AD18: =IF($AD$11<>"",B17,"") | AE18: =IF($AE$11<>"",B17,"") | AF18: =IF($AF$11<>"",B17,"") | AG18: =IF($AG$11<>"",B17,"") | AH18: =IF($AH$11<>"",B17,"") | AI18: =IF($AI$11<>"",B17,"") | AJ18: =IF($AJ$11<>"",B17,"") | AK18: =IF($AK$11<>"",B17,"") | AL18: =IF($AL$11<>"",B17,"") | AM18: =IF($AM$11<>"",B17,"") | AN18: =IF($AN$11<>"",B17,"") | AO18: =IF($AO$11<>"",B17,"") | AP18: =IF($AP$11<>"",B17,"") | AQ18: =IF($AQ$11<>"",B17,"") | AR18: =IF($AR$11<>"",B17,"") | AS18: =IF($AS$11<>"",B17,"") | AT18: =IF($AT$11<>"",B17,"") | AU18: =IF($AU$11<>"",B17,"") | AV18: =IF($AV$11<>"",B17,"") | AW18: =IF($AW$11<>"",B17,"") | AX18: =IF($AX$11<>"",B17,"") | AY18: =IF($AY$11<>"",B17,"") | AZ18: =IF($AZ$11<>"",B17,"") | BA18: =IF($BA$11<>"",B17,"") | BB18: =IF($BB$11<>"",B17,"") | BC18: =IF($BC$11<>"",B17,"") | BD18: =IF($BD$11<>"",B17,"") | BE18: =IF($BE$11<>"",B17,"") | BF18: =IF($BF$11<>"",B17,"") | BG18: =IF($BG$11<>"",B17,"") | BH18: =IF($BH$11<>"",B17,"") | BI18: =IF($BI$11<>"",B17,"") | BJ18: =IF($BJ$11<>"",B17,"") | BK18: =IF($BK$11<>"",B17,"") | BL18: =IF($BL$11<>"",B17,"") | BM18: =IF($BM$11<>"",B17,"") | BN18: =IF($BN$11<>"",B17,"") | BO18: =IF($BO$11<>"",B17,"") | BP18: =IF($BP$11<>"",B17,"") | BQ18: =IF($BQ$11<>"",B17,"") | BR18: =IF($BR$11<>"",B17,"") | BS18: =IF($BS$11<>"",B17,"") | BT18: =IF($BT$11<>"",B17,"") | BU18: =IF($BU$11<>"",B17,"") | BV18: =IF($BV$11<>"",B17,"") | BW18: =IF($BW$11<>"",B17,"") | BX18: =IF($BX$11<>"",B17,"") | BY18: =IF($BY$11<>"",B17,"") | BZ18: =IF($BZ$11<>"",B17,"") | CA18: =IF($CA$11<>"",B17,"") | CB18: =IF($CB$11<>"",B17,"") | CC18: =IF($CC$11<>"",B17,"") | CD18: =IF($CD$11<>"",B17,"") | CE18: =IF($CE$11<>"",B17,"") | CF18: =IF($CF$11<>"",B17,"") | CG18: =IF($CG$11<>"",B17,"") | CH18: =IF($CH$11<>"",B17,"") | CI18: =IF($CI$11<>"",B17,"") | CJ18: =IF($CJ$11<>"",B17,"") | CK18: =IF($CK$11<>"",B17,"") | CL18: =IF($CL$11<>"",B17,"") | CM18: =IF($CM$11<>"",B17,"") | CN18: =IF($CN$11<>"",B17,"") | CO18: =IF($CO$11<>"",B17,"") | CP18: =IF($CP$11<>"",B17,"") | CQ18: =IF($CQ$11<>"",B17,"") | CR18: =IF($CR$11<>"",B17,"") | CS18: =IF(CS17<>"",B$17,"") | CT18: =IF($CT$11<>"",B17,"") | CU18: =IF($CU$11<>"",B17,"") | CV18: =IF($CV$11<>"",B17,"") | CW18: =IF($CW$11<>"",B17,"") | CX18: =IF($CX$11<>"",B17,"") | CY18: =IF($CY$11<>"",B17,"") | CZ18: =IF($CZ$11<>"",B17,"") | DA18: =IF($DA$11<>"",B17,"") | DB18: =IF($DB$11<>"",B17,"") | DC18: =IF($DC$11<>"",B17,"") | DD18: =IF($DD$11<>"",B17,"") | DE18: =IF($DE$11<>"",B17,"") | DF18: =IF($DF$11<>"",B17,"") | DG18: =IF($DG$11<>"",B17,"") | DH18: =IF($DH$11<>"",B17,"") | DI18: =IF($DI$11<>"",B17,"") | DJ18: =IF($DJ$11<>"",B17,"") | DK18: =IF($DK$11<>"",$B17,"") | DL18: =IF($DL$11<>"",$B17,"") | DM18: =IF($DM$11<>"",$B17,"") | DN18: =IF($DN$11<>"",$B17,"") | DO18: =IF($DO$11<>"",$B17,"") | DP18: =IF($DP$11<>"",$B17,"") | DQ18: =IF($DQ$11<>"",$B17,"") | DR18: =IF($DR$11<>"",$B17,"") | DS18: =IF($DS$11<>"",$B17,"") | DT18: =IF($DT$11<>"",$B17,"") | DU18: =IF($DU$11<>"",$B17,"") | DV18: =IF($DV$11<>"",$B17,"") | DY18: BANDANA | DZ18: AMARLO LTDA | EA18: A1 | EB18: ALL BLACK | EC18: 530 ML
A19: =IF(PEDIDO!C44<>"",PEDIDO!B44,"") | B19: =IF(PEDIDO!X44<>"",PEDIDO!X44,"") | C19: =IF(PEDIDO!AA44<>"",PEDIDO!AA44,"") | D19: =IF(PEDIDO!AD44<>"",PEDIDO!AD44,"") | E19: =IF(PEDIDO!AG44<>"",PEDIDO!AG44,"") | F19: =IF(PEDIDO!AJ44<>"",PEDIDO!AJ44,"") | J19: =IF(PEDIDO!C43<>"",PEDIDO!B43,"") | K19: =IF($K$11<>"",B18,"") | L19: =IF($L$11<>"",B18,"") | M19: =IF($M$11<>"",B18,"") | N19: =IF($N$11<>"",B18,"") | O19: =IF($O$11<>"",B18,"") | P19: =IF($P$11<>"",B18,"") | Q19: =IF($Q$11<>"",B18,"") | R19: =IF($R$11<>"",B18,"") | S19: =IF($S$11<>"",B18,"") | T19: =IF($T$11<>"",B18,"") | U19: =IF($U$11<>"",B18,"") | V19: =IF($V$11<>"",B18,"") | X19: =IF($X$11<>"",B18,"") | Y19: =IF($Y$11<>"",B18,"") | Z19: =IF($Z$11<>"",B18,"") | AA19: =IF($AA$11<>"",B18,"") | AB19: =IF($AB$11<>"",B18,"") | AC19: =IF($AC$11<>"",B18,"") | AD19: =IF($AD$11<>"",B18,"") | AE19: =IF($AE$11<>"",B18,"") | AF19: =IF($AF$11<>"",B18,"") | AG19: =IF($AG$11<>"",B18,"") | AH19: =IF($AH$11<>"",B18,"") | AI19: =IF($AI$11<>"",B18,"") | AJ19: =IF($AJ$11<>"",B18,"") | AK19: =IF($AK$11<>"",B18,"") | AL19: =IF($AL$11<>"",B18,"") | AM19: =IF($AM$11<>"",B18,"") | AN19: =IF($AN$11<>"",B18,"") | AO19: =IF($AO$11<>"",B18,"") | AP19: =IF($AP$11<>"",B18,"") | AQ19: =IF($AQ$11<>"",B18,"") | AR19: =IF($AR$11<>"",B18,"") | AS19: =IF($AS$11<>"",B18,"") | AT19: =IF($AT$11<>"",B18,"") | AU19: =IF($AU$11<>"",B18,"") | AV19: =IF($AV$11<>"",B18,"") | AW19: =IF($AW$11<>"",B18,"") | AX19: =IF($AX$11<>"",B18,"") | AY19: =IF($AY$11<>"",B18,"") | AZ19: =IF($AZ$11<>"",B18,"") | BA19: =IF($BA$11<>"",B18,"") | BB19: =IF($BB$11<>"",B18,"") | BC19: =IF($BC$11<>"",B18,"") | BD19: =IF($BD$11<>"",B18,"") | BE19: =IF($BE$11<>"",B18,"") | BF19: =IF($BF$11<>"",B18,"") | BG19: =IF($BG$11<>"",B18,"") | BH19: =IF($BH$11<>"",B18,"") | BI19: =IF($BI$11<>"",B18,"") | BJ19: =IF($BJ$11<>"",B18,"") | BK19: =IF($BK$11<>"",B18,"") | BL19: =IF($BL$11<>"",B18,"") | BM19: =IF($BM$11<>"",B18,"") | BN19: =IF($BN$11<>"",B18,"") | BO19: =IF($BO$11<>"",B18,"") | BP19: =IF($BP$11<>"",B18,"") | BQ19: =IF($BQ$11<>"",B18,"") | BR19: =IF($BR$11<>"",B18,"") | BS19: =IF($BS$11<>"",B18,"") | BT19: =IF($BT$11<>"",B18,"") | BU19: =IF($BU$11<>"",B18,"") | BV19: =IF($BV$11<>"",B18,"") | BW19: =IF($BW$11<>"",B18,"") | BX19: =IF($BX$11<>"",B18,"") | BY19: =IF($BY$11<>"",B18,"") | BZ19: =IF($BZ$11<>"",B18,"") | CA19: =IF($CA$11<>"",B18,"") | CB19: =IF($CB$11<>"",B18,"") | CC19: =IF($CC$11<>"",B18,"") | CD19: =IF($CD$11<>"",B18,"") | CE19: =IF($CE$11<>"",B18,"") | CF19: =IF($CF$11<>"",B18,"") | CG19: =IF($CG$11<>"",B18,"") | CH19: =IF($CH$11<>"",B18,"") | CI19: =IF($CI$11<>"",B18,"") | CJ19: =IF($CJ$11<>"",B18,"") | CK19: =IF($CK$11<>"",B18,"") | CL19: =IF($CL$11<>"",B18,"") | CM19: =IF($CM$11<>"",B18,"") | CN19: =IF($CN$11<>"",B18,"") | CO19: =IF($CO$11<>"",B18,"") | CP19: =IF($CP$11<>"",B18,"") | CQ19: =IF($CQ$11<>"",B18,"") | CR19: =IF($CR$11<>"",B18,"") | CS19: =IF(CS18<>"",$B18,"") | CT19: =IF($CT$11<>"",B18,"") | CU19: =IF($CU$11<>"",B18,"") | CV19: =IF($CV$11<>"",B18,"") | CW19: =IF($CW$11<>"",B18,"") | CX19: =IF($CX$11<>"",B18,"") | CY19: =IF($CY$11<>"",B18,"") | CZ19: =IF($CZ$11<>"",B18,"") | DA19: =IF($DA$11<>"",B18,"") | DB19: =IF($DB$11<>"",B18,"") | DC19: =IF($DC$11<>"",B18,"") | DD19: =IF($DD$11<>"",B18,"") | DE19: =IF($DE$11<>"",B18,"") | DF19: =IF($DF$11<>"",B18,"") | DG19: =IF($DG$11<>"",B18,"") | DH19: =IF($DH$11<>"",B18,"") | DI19: =IF($DI$11<>"",B18,"") | DJ19: =IF($DJ$11<>"",B18,"") | DK19: =IF($DK$11<>"",$B18,"") | DL19: =IF($DL$11<>"",$B18,"") | DM19: =IF($DM$11<>"",$B18,"") | DN19: =IF($DN$11<>"",$B18,"") | DO19: =IF($DO$11<>"",$B18,"") | DP19: =IF($DP$11<>"",$B18,"") | DQ19: =IF($DQ$11<>"",$B18,"") | DR19: =IF($DR$11<>"",$B18,"") | DS19: =IF($DS$11<>"",$B18,"") | DT19: =IF($DT$11<>"",$B18,"") | DU19: =IF($DU$11<>"",$B18,"") | DV19: =IF($DV$11<>"",$B18,"") | DY19: BATA | DZ19: KAPAZI | EA19: A7SK | EB19: ALL WHITE | EC19: 680ML
A20: =IF(PEDIDO!C45<>"",PEDIDO!B45,"") | B20: =IF(PEDIDO!X45<>"",PEDIDO!X45,"") | C20: =IF(PEDIDO!AA45<>"",PEDIDO!AA45,"") | D20: =IF(PEDIDO!AD45<>"",PEDIDO!AD45,"") | E20: =IF(PEDIDO!AG45<>"",PEDIDO!AG45,"") | F20: =IF(PEDIDO!AJ45<>"",PEDIDO!AJ45,"") | J20: =IF(PEDIDO!C44<>"",PEDIDO!B44,"") | K20: =IF($K$11<>"",B19,"") | L20: =IF($L$11<>"",B19,"") | M20: =IF($M$11<>"",B19,"") | N20: =IF($N$11<>"",B19,"") | O20: =IF($O$11<>"",B19,"") | P20: =IF($P$11<>"",B19,"") | Q20: =IF($Q$11<>"",B19,"") | R20: =IF($R$11<>"",B19,"") | S20: =IF($S$11<>"",B19,"") | T20: =IF($T$11<>"",B19,"") | U20: =IF($U$11<>"",B19,"") | V20: =IF($V$11<>"",B19,"") | X20: =IF($X$11<>"",B19,"") | Y20: =IF($Y$11<>"",B19,"") | Z20: =IF($Z$11<>"",B19,"") | AA20: =IF($AA$11<>"",B19,"") | AB20: =IF($AB$11<>"",B19,"") | AC20: =IF($AC$11<>"",B19,"") | AD20: =IF($AD$11<>"",B19,"") | AE20: =IF($AE$11<>"",B19,"") | AF20: =IF($AF$11<>"",B19,"") | AG20: =IF($AG$11<>"",B19,"") | AH20: =IF($AH$11<>"",B19,"") | AI20: =IF($AI$11<>"",B19,"") | AJ20: =IF($AJ$11<>"",B19,"") | AK20: =IF($AK$11<>"",B19,"") | AL20: =IF($AL$11<>"",B19,"") | AM20: =IF($AM$11<>"",B19,"") | AN20: =IF($AN$11<>"",B19,"") | AO20: =IF($AO$11<>"",B19,"") | AP20: =IF($AP$11<>"",B19,"") | AQ20: =IF($AQ$11<>"",B19,"") | AR20: =IF($AR$11<>"",B19,"") | AS20: =IF($AS$11<>"",B19,"") | AT20: =IF($AT$11<>"",B19,"") | AU20: =IF($AU$11<>"",B19,"") | AV20: =IF($AV$11<>"",B19,"") | AW20: =IF($AW$11<>"",B19,"") | AX20: =IF($AX$11<>"",B19,"") | AY20: =IF($AY$11<>"",B19,"") | AZ20: =IF($AZ$11<>"",B19,"") | BA20: =IF($BA$11<>"",B19,"") | BB20: =IF($BB$11<>"",B19,"") | BC20: =IF($BC$11<>"",B19,"") | BD20: =IF($BD$11<>"",B19,"") | BE20: =IF($BE$11<>"",B19,"") | BF20: =IF($BF$11<>"",B19,"") | BG20: =IF($BG$11<>"",B19,"") | BH20: =IF($BH$11<>"",B19,"") | BI20: =IF($BI$11<>"",B19,"") | BJ20: =IF($BJ$11<>"",B19,"") | BK20: =IF($BK$11<>"",B19,"") | BL20: =IF($BL$11<>"",B19,"") | BM20: =IF($BM$11<>"",B19,"") | BN20: =IF($BN$11<>"",B19,"") | BO20: =IF($BO$11<>"",B19,"") | BP20: =IF($BP$11<>"",B19,"") | BQ20: =IF($BQ$11<>"",B19,"") | BR20: =IF($BR$11<>"",B19,"") | BS20: =IF($BS$11<>"",B19,"") | BT20: =IF($BT$11<>"",B19,"") | BU20: =IF($BU$11<>"",B19,"") | BV20: =IF($BV$11<>"",B19,"") | BW20: =IF($BW$11<>"",B19,"") | BX20: =IF($BX$11<>"",B19,"") | BY20: =IF($BY$11<>"",B19,"") | BZ20: =IF($BZ$11<>"",B19,"") | CA20: =IF($CA$11<>"",B19,"") | CB20: =IF($CB$11<>"",B19,"") | CC20: =IF($CC$11<>"",B19,"") | CD20: =IF($CD$11<>"",B19,"") | CE20: =IF($CE$11<>"",B19,"") | CF20: =IF($CF$11<>"",B19,"") | CG20: =IF($CG$11<>"",B19,"") | CH20: =IF($CH$11<>"",B19,"") | CI20: =IF($CI$11<>"",B19,"") | CJ20: =IF($CJ$11<>"",B19,"") | CK20: =IF($CK$11<>"",B19,"") | CL20: =IF($CL$11<>"",B19,"") | CM20: =IF($CM$11<>"",B19,"") | CN20: =IF($CN$11<>"",B19,"") | CO20: =IF($CO$11<>"",B19,"") | CP20: =IF($CP$11<>"",B19,"") | CQ20: =IF($CQ$11<>"",B19,"") | CR20: =IF($CR$11<>"",B19,"") | CS20: =IF(CS19<>"",B$19,"") | CT20: =IF($CT$11<>"",B19,"") | CU20: =IF($CU$11<>"",B19,"") | CV20: =IF($CV$11<>"",B19,"") | CW20: =IF($CW$11<>"",B19,"") | CX20: =IF($CX$11<>"",B19,"") | CY20: =IF($CY$11<>"",B19,"") | CZ20: =IF($CZ$11<>"",B19,"") | DA20: =IF($DA$11<>"",B19,"") | DB20: =IF($DB$11<>"",B19,"") | DC20: =IF($DC$11<>"",B19,"") | DD20: =IF($DD$11<>"",B19,"") | DE20: =IF($DE$11<>"",B19,"") | DF20: =IF($DF$11<>"",B19,"") | DG20: =IF($DG$11<>"",B19,"") | DH20: =IF($DH$11<>"",B19,"") | DI20: =IF($DI$11<>"",B19,"") | DJ20: =IF($DJ$11<>"",B19,"") | DK20: =IF($DK$11<>"",$B19,"") | DL20: =IF($DL$11<>"",$B19,"") | DM20: =IF($DM$11<>"",$B19,"") | DN20: =IF($DN$11<>"",$B19,"") | DO20: =IF($DO$11<>"",$B19,"") | DP20: =IF($DP$11<>"",$B19,"") | DQ20: =IF($DQ$11<>"",$B19,"") | DR20: =IF($DR$11<>"",$B19,"") | DS20: =IF($DS$11<>"",$B19,"") | DT20: =IF($DT$11<>"",$B19,"") | DU20: =IF($DU$11<>"",$B19,"") | DV20: =IF($DV$11<>"",$B19,"") | DY20: BATA INFANTIL | DZ20: REAL CALCADOS - LOJA 11 | EA20: ABC DA CONSTRUCAO | EB20: ALLOY | EC20: 700ML
A21: =IF(PEDIDO!C46<>"",PEDIDO!B46,"") | B21: =IF(PEDIDO!X46<>"",PEDIDO!X46,"") | C21: =IF(PEDIDO!AA46<>"",PEDIDO!AA46,"") | D21: =IF(PEDIDO!AD46<>"",PEDIDO!AD46,"") | E21: =IF(PEDIDO!AG46<>"",PEDIDO!AG46,"") | F21: =IF(PEDIDO!AJ46<>"",PEDIDO!AJ46,"") | J21: =IF(PEDIDO!C45<>"",PEDIDO!B45,"") | K21: =IF($K$11<>"",B20,"") | L21: =IF($L$11<>"",B20,"") | M21: =IF($M$11<>"",B20,"") | N21: =IF($N$11<>"",B20,"") | O21: =IF($O$11<>"",B20,"") | P21: =IF($P$11<>"",B20,"") | Q21: =IF($Q$11<>"",B20,"") | R21: =IF($R$11<>"",B20,"") | S21: =IF($S$11<>"",B20,"") | T21: =IF($T$11<>"",B20,"") | U21: =IF($U$11<>"",B20,"") | V21: =IF($V$11<>"",B20,"") | X21: =IF($X$11<>"",B20,"") | Y21: =IF($Y$11<>"",B20,"") | Z21: =IF($Z$11<>"",B20,"") | AA21: =IF($AA$11<>"",B20,"") | AB21: =IF($AB$11<>"",B20,"") | AC21: =IF($AC$11<>"",B20,"") | AD21: =IF($AD$11<>"",B20,"") | AE21: =IF($AE$11<>"",B20,"") | AF21: =IF($AF$11<>"",B20,"") | AG21: =IF($AG$11<>"",B20,"") | AH21: =IF($AH$11<>"",B20,"") | AI21: =IF($AI$11<>"",B20,"") | AJ21: =IF($AJ$11<>"",B20,"") | AK21: =IF($AK$11<>"",B20,"") | AL21: =IF($AL$11<>"",B20,"") | AM21: =IF($AM$11<>"",B20,"") | AN21: =IF($AN$11<>"",B20,"") | AO21: =IF($AO$11<>"",B20,"") | AP21: =IF($AP$11<>"",B20,"") | AQ21: =IF($AQ$11<>"",B20,"") | AR21: =IF($AR$11<>"",B20,"") | AS21: =IF($AS$11<>"",B20,"") | AT21: =IF($AT$11<>"",B20,"") | AU21: =IF($AU$11<>"",B20,"") | AV21: =IF($AV$11<>"",B20,"") | AW21: =IF($AW$11<>"",B20,"") | AX21: =IF($AX$11<>"",B20,"") | AY21: =IF($AY$11<>"",B20,"") | AZ21: =IF($AZ$11<>"",B20,"") | BA21: =IF($BA$11<>"",B20,"") | BB21: =IF($BB$11<>"",B20,"") | BC21: =IF($BC$11<>"",B20,"") | BD21: =IF($BD$11<>"",B20,"") | BE21: =IF($BE$11<>"",B20,"") | BF21: =IF($BF$11<>"",B20,"") | BG21: =IF($BG$11<>"",B20,"") | BH21: =IF($BH$11<>"",B20,"") | BI21: =IF($BI$11<>"",B20,"") | BJ21: =IF($BJ$11<>"",B20,"") | BK21: =IF($BK$11<>"",B20,"") | BL21: =IF($BL$11<>"",B20,"") | BM21: =IF($BM$11<>"",B20,"") | BN21: =IF($BN$11<>"",B20,"") | BO21: =IF($BO$11<>"",B20,"") | BP21: =IF($BP$11<>"",B20,"") | BQ21: =IF($BQ$11<>"",B20,"") | BR21: =IF($BR$11<>"",B20,"") | BS21: =IF($BS$11<>"",B20,"") | BT21: =IF($BT$11<>"",B20,"") | BU21: =IF($BU$11<>"",B20,"") | BV21: =IF($BV$11<>"",B20,"") | BW21: =IF($BW$11<>"",B20,"") | BX21: =IF($BX$11<>"",B20,"") | BY21: =IF($BY$11<>"",B20,"") | BZ21: =IF($BZ$11<>"",B20,"") | CA21: =IF($CA$11<>"",B20,"") | CB21: =IF($CB$11<>"",B20,"") | CC21: =IF($CC$11<>"",B20,"") | CD21: =IF($CD$11<>"",B20,"") | CE21: =IF($CE$11<>"",B20,"") | CF21: =IF($CF$11<>"",B20,"") | CG21: =IF($CG$11<>"",B20,"") | CH21: =IF($CH$11<>"",B20,"") | CI21: =IF($CI$11<>"",B20,"") | CJ21: =IF($CJ$11<>"",B20,"") | CK21: =IF($CK$11<>"",B20,"") | CL21: =IF($CL$11<>"",B20,"") | CM21: =IF($CM$11<>"",B20,"") | CN21: =IF($CN$11<>"",B20,"") | CO21: =IF($CO$11<>"",B20,"") | CP21: =IF($CP$11<>"",B20,"") | CQ21: =IF($CQ$11<>"",B20,"") | CR21: =IF($CR$11<>"",B20,"") | CS21: =IF(CS20<>"",B$20,"") | CT21: =IF($CT$11<>"",B20,"") | CU21: =IF($CU$11<>"",B20,"") | CV21: =IF($CV$11<>"",B20,"") | CW21: =IF($CW$11<>"",B20,"") | CX21: =IF($CX$11<>"",B20,"") | CY21: =IF($CY$11<>"",B20,"") | CZ21: =IF($CZ$11<>"",B20,"") | DA21: =IF($DA$11<>"",B20,"") | DB21: =IF($DB$11<>"",B20,"") | DC21: =IF($DC$11<>"",B20,"") | DD21: =IF($DD$11<>"",B20,"") | DE21: =IF($DE$11<>"",B20,"") | DF21: =IF($DF$11<>"",B20,"") | DG21: =IF($DG$11<>"",B20,"") | DH21: =IF($DH$11<>"",B20,"") | DI21: =IF($DI$11<>"",B20,"") | DJ21: =IF($DJ$11<>"",B20,"") | DK21: =IF($DK$11<>"",$B20,"") | DL21: =IF($DL$11<>"",$B20,"") | DM21: =IF($DM$11<>"",$B20,"") | DN21: =IF($DN$11<>"",$B20,"") | DO21: =IF($DO$11<>"",$B20,"") | DP21: =IF($DP$11<>"",$B20,"") | DQ21: =IF($DQ$11<>"",$B20,"") | DR21: =IF($DR$11<>"",$B20,"") | DS21: =IF($DS$11<>"",$B20,"") | DT21: =IF($DT$11<>"",$B20,"") | DU21: =IF($DU$11<>"",$B20,"") | DV21: =IF($DV$11<>"",$B20,"") | DY21: BATA INFANTIL MASCULINO | DZ21: EBAZAR.COM.BR.LTDA | EA21: ABRANGE | EB21: ALMERIA | EC21: 750ML
